return { { ["y"] = 4, ["x"] = 0, ["name"] = "cottages:roof_straw", ["z"] = 7, ["meta"] = { ["inventory"] = {  }, ["fields"] = {  } }, ["param2"] = 1, ["param1"] = 125 }, { ["y"] = 4, ["x"] = 0, ["name"] = "cottages:roof_straw", ["z"] = 8, ["meta"] = { ["inventory"] = {  }, ["fields"] = {  } }, ["param2"] = 1, ["param1"] = 109 }, { ["y"] = 4, ["x"] = 0, ["name"] = "cottages:roof_straw", ["z"] = 9, ["meta"] = { ["inventory"] = {  }, ["fields"] = {  } }, ["param2"] = 1, ["param1"] = 125 }, { ["y"] = 4, ["x"] = 0, ["name"] = "cottages:roof_straw", ["z"] = 10, ["meta"] = { ["inventory"] = {  }, ["fields"] = {  } }, ["param2"] = 1, ["param1"] = 141 }, { ["y"] = 4, ["x"] = 0, ["name"] = "cottages:roof_straw", ["z"] = 11, ["meta"] = { ["inventory"] = {  }, ["fields"] = {  } }, ["param2"] = 1, ["param1"] = 157 }, { ["y"] = 4, ["x"] = 0, ["name"] = "cottages:roof_straw", ["z"] = 12, ["meta"] = { ["inventory"] = {  }, ["fields"] = {  } }, ["param2"] = 1, ["param1"] = 141 }, { ["y"] = 4, ["x"] = 0, ["name"] = "cottages:roof_straw", ["z"] = 13, ["meta"] = { ["inventory"] = {  }, ["fields"] = {  } }, ["param2"] = 1, ["param1"] = 157 }, { ["y"] = 4, ["x"] = 0, ["name"] = "cottages:roof_straw", ["z"] = 14, ["meta"] = { ["inventory"] = {  }, ["fields"] = {  } }, ["param2"] = 1, ["param1"] = 141 }, { ["y"] = 4, ["x"] = 0, ["name"] = "cottages:roof_straw", ["z"] = 15, ["meta"] = { ["inventory"] = {  }, ["fields"] = {  } }, ["param2"] = 1, ["param1"] = 157 }, { ["y"] = 4, ["x"] = 0, ["name"] = "cottages:roof_straw", ["z"] = 16, ["meta"] = { ["inventory"] = {  }, ["fields"] = {  } }, ["param2"] = 1, ["param1"] = 141 }, { ["y"] = 4, ["x"] = 0, ["name"] = "cottages:roof_straw", ["z"] = 17, ["meta"] = { ["inventory"] = {  }, ["fields"] = {  } }, ["param2"] = 1, ["param1"] = 157 }, { ["y"] = 4, ["x"] = 0, ["name"] = "cottages:roof_straw", ["z"] = 18, ["meta"] = { ["inventory"] = {  }, ["fields"] = {  } }, ["param2"] = 1, ["param1"] = 141 }, { ["y"] = 4, ["x"] = 0, ["name"] = "cottages:roof_straw", ["z"] = 19, ["meta"] = { ["inventory"] = {  }, ["fields"] = {  } }, ["param2"] = 1, ["param1"] = 157 }, { ["y"] = 4, ["x"] = 0, ["name"] = "cottages:roof_straw", ["z"] = 20, ["meta"] = { ["inventory"] = {  }, ["fields"] = {  } }, ["param2"] = 1, ["param1"] = 141 }, { ["y"] = 4, ["x"] = 0, ["name"] = "cottages:roof_straw", ["z"] = 21, ["meta"] = { ["inventory"] = {  }, ["fields"] = {  } }, ["param2"] = 1, ["param1"] = 157 }, { ["y"] = 4, ["x"] = 0, ["name"] = "cottages:roof_straw", ["z"] = 22, ["meta"] = { ["inventory"] = {  }, ["fields"] = {  } }, ["param2"] = 1, ["param1"] = 141 }, { ["y"] = 0, ["x"] = 1, ["name"] = "default:cobble", ["z"] = 8, ["meta"] = { ["inventory"] = {  }, ["fields"] = {  } }, ["param2"] = 0, ["param1"] = 0 }, { ["y"] = 0, ["x"] = 1, ["name"] = "default:cobble", ["z"] = 9, ["meta"] = { ["inventory"] = {  }, ["fields"] = {  } }, ["param2"] = 0, ["param1"] = 0 }, { ["y"] = 0, ["x"] = 1, ["name"] = "default:cobble", ["z"] = 10, ["meta"] = { ["inventory"] = {  }, ["fields"] = {  } }, ["param2"] = 0, ["param1"] = 0 }, { ["y"] = 0, ["x"] = 1, ["name"] = "default:cobble", ["z"] = 11, ["meta"] = { ["inventory"] = {  }, ["fields"] = {  } }, ["param2"] = 0, ["param1"] = 0 }, { ["y"] = 0, ["x"] = 1, ["name"] = "default:cobble", ["z"] = 12, ["meta"] = { ["inventory"] = {  }, ["fields"] = {  } }, ["param2"] = 0, ["param1"] = 0 }, { ["y"] = 0, ["x"] = 1, ["name"] = "default:cobble", ["z"] = 13, ["meta"] = { ["inventory"] = {  }, ["fields"] = {  } }, ["param2"] = 0, ["param1"] = 0 }, { ["y"] = 0, ["x"] = 1, ["name"] = "default:cobble", ["z"] = 14, ["meta"] = { ["inventory"] = {  }, ["fields"] = {  } }, ["param2"] = 0, ["param1"] = 0 }, { ["y"] = 0, ["x"] = 1, ["name"] = "default:cobble", ["z"] = 15, ["meta"] = { ["inventory"] = {  }, ["fields"] = {  } }, ["param2"] = 0, ["param1"] = 0 }, { ["y"] = 0, ["x"] = 1, ["name"] = "default:cobble", ["z"] = 16, ["meta"] = { ["inventory"] = {  }, ["fields"] = {  } }, ["param2"] = 0, ["param1"] = 0 }, { ["y"] = 0, ["x"] = 1, ["name"] = "default:cobble", ["z"] = 17, ["meta"] = { ["inventory"] = {  }, ["fields"] = {  } }, ["param2"] = 0, ["param1"] = 0 }, { ["y"] = 0, ["x"] = 1, ["name"] = "default:cobble", ["z"] = 18, ["meta"] = { ["inventory"] = {  }, ["fields"] = {  } }, ["param2"] = 0, ["param1"] = 0 }, { ["y"] = 0, ["x"] = 1, ["name"] = "default:cobble", ["z"] = 19, ["meta"] = { ["inventory"] = {  }, ["fields"] = {  } }, ["param2"] = 0, ["param1"] = 0 }, { ["y"] = 0, ["x"] = 1, ["name"] = "default:cobble", ["z"] = 20, ["meta"] = { ["inventory"] = {  }, ["fields"] = {  } }, ["param2"] = 0, ["param1"] = 0 }, { ["y"] = 0, ["x"] = 1, ["name"] = "default:cobble", ["z"] = 21, ["meta"] = { ["inventory"] = {  }, ["fields"] = {  } }, ["param2"] = 0, ["param1"] = 0 }, { ["y"] = 0, ["x"] = 1, ["name"] = "default:cobble", ["z"] = 22, ["meta"] = { ["inventory"] = {  }, ["fields"] = {  } }, ["param2"] = 0, ["param1"] = 0 }, { ["y"] = 1, ["x"] = 1, ["name"] = "cottages:loam", ["z"] = 8, ["meta"] = { ["inventory"] = {  }, ["fields"] = {  } }, ["param2"] = 0, ["param1"] = 0 }, { ["y"] = 1, ["x"] = 1, ["name"] = "cottages:loam", ["z"] = 9, ["meta"] = { ["inventory"] = {  }, ["fields"] = {  } }, ["param2"] = 0, ["param1"] = 0 }, { ["y"] = 1, ["x"] = 1, ["name"] = "cottages:loam", ["z"] = 10, ["meta"] = { ["inventory"] = {  }, ["fields"] = {  } }, ["param2"] = 0, ["param1"] = 0 }, { ["y"] = 1, ["x"] = 1, ["name"] = "cottages:loam", ["z"] = 11, ["meta"] = { ["inventory"] = {  }, ["fields"] = {  } }, ["param2"] = 0, ["param1"] = 0 }, { ["y"] = 1, ["x"] = 1, ["name"] = "cottages:loam", ["z"] = 12, ["meta"] = { ["inventory"] = {  }, ["fields"] = {  } }, ["param2"] = 0, ["param1"] = 0 }, { ["y"] = 1, ["x"] = 1, ["name"] = "cottages:loam", ["z"] = 13, ["meta"] = { ["inventory"] = {  }, ["fields"] = {  } }, ["param2"] = 0, ["param1"] = 0 }, { ["y"] = 1, ["x"] = 1, ["name"] = "cottages:loam", ["z"] = 14, ["meta"] = { ["inventory"] = {  }, ["fields"] = {  } }, ["param2"] = 0, ["param1"] = 0 }, { ["y"] = 1, ["x"] = 1, ["name"] = "cottages:loam", ["z"] = 15, ["meta"] = { ["inventory"] = {  }, ["fields"] = {  } }, ["param2"] = 0, ["param1"] = 0 }, { ["y"] = 1, ["x"] = 1, ["name"] = "cottages:loam", ["z"] = 16, ["meta"] = { ["inventory"] = {  }, ["fields"] = {  } }, ["param2"] = 0, ["param1"] = 0 }, { ["y"] = 1, ["x"] = 1, ["name"] = "cottages:loam", ["z"] = 17, ["meta"] = { ["inventory"] = {  }, ["fields"] = {  } }, ["param2"] = 0, ["param1"] = 0 }, { ["y"] = 1, ["x"] = 1, ["name"] = "cottages:loam", ["z"] = 18, ["meta"] = { ["inventory"] = {  }, ["fields"] = {  } }, ["param2"] = 0, ["param1"] = 0 }, { ["y"] = 1, ["x"] = 1, ["name"] = "cottages:loam", ["z"] = 19, ["meta"] = { ["inventory"] = {  }, ["fields"] = {  } }, ["param2"] = 0, ["param1"] = 0 }, { ["y"] = 1, ["x"] = 1, ["name"] = "cottages:loam", ["z"] = 20, ["meta"] = { ["inventory"] = {  }, ["fields"] = {  } }, ["param2"] = 0, ["param1"] = 0 }, { ["y"] = 1, ["x"] = 1, ["name"] = "cottages:loam", ["z"] = 21, ["meta"] = { ["inventory"] = {  }, ["fields"] = {  } }, ["param2"] = 0, ["param1"] = 0 }, { ["y"] = 1, ["x"] = 1, ["name"] = "cottages:loam", ["z"] = 22, ["meta"] = { ["inventory"] = {  }, ["fields"] = {  } }, ["param2"] = 0, ["param1"] = 0 }, { ["y"] = 2, ["x"] = 1, ["name"] = "cottages:loam", ["z"] = 8, ["meta"] = { ["inventory"] = {  }, ["fields"] = {  } }, ["param2"] = 0, ["param1"] = 0 }, { ["y"] = 2, ["x"] = 1, ["name"] = "cottages:loam", ["z"] = 9, ["meta"] = { ["inventory"] = {  }, ["fields"] = {  } }, ["param2"] = 0, ["param1"] = 0 }, { ["y"] = 2, ["x"] = 1, ["name"] = "cottages:glass_pane", ["z"] = 10, ["meta"] = { ["inventory"] = {  }, ["fields"] = {  } }, ["param2"] = 3, ["param1"] = 188 }, { ["y"] = 2, ["x"] = 1, ["name"] = "cottages:loam", ["z"] = 11, ["meta"] = { ["inventory"] = {  }, ["fields"] = {  } }, ["param2"] = 0, ["param1"] = 0 }, { ["y"] = 2, ["x"] = 1, ["name"] = "cottages:glass_pane", ["z"] = 12, ["meta"] = { ["inventory"] = {  }, ["fields"] = {  } }, ["param2"] = 3, ["param1"] = 188 }, { ["y"] = 2, ["x"] = 1, ["name"] = "cottages:loam", ["z"] = 13, ["meta"] = { ["inventory"] = {  }, ["fields"] = {  } }, ["param2"] = 0, ["param1"] = 0 }, { ["y"] = 2, ["x"] = 1, ["name"] = "cottages:glass_pane", ["z"] = 14, ["meta"] = { ["inventory"] = {  }, ["fields"] = {  } }, ["param2"] = 3, ["param1"] = 188 }, { ["y"] = 2, ["x"] = 1, ["name"] = "cottages:loam", ["z"] = 15, ["meta"] = { ["inventory"] = {  }, ["fields"] = {  } }, ["param2"] = 0, ["param1"] = 0 }, { ["y"] = 2, ["x"] = 1, ["name"] = "cottages:glass_pane", ["z"] = 16, ["meta"] = { ["inventory"] = {  }, ["fields"] = {  } }, ["param2"] = 3, ["param1"] = 188 }, { ["y"] = 2, ["x"] = 1, ["name"] = "cottages:loam", ["z"] = 17, ["meta"] = { ["inventory"] = {  }, ["fields"] = {  } }, ["param2"] = 0, ["param1"] = 0 }, { ["y"] = 2, ["x"] = 1, ["name"] = "cottages:glass_pane", ["z"] = 18, ["meta"] = { ["inventory"] = {  }, ["fields"] = {  } }, ["param2"] = 3, ["param1"] = 188 }, { ["y"] = 2, ["x"] = 1, ["name"] = "cottages:loam", ["z"] = 19, ["meta"] = { ["inventory"] = {  }, ["fields"] = {  } }, ["param2"] = 0, ["param1"] = 0 }, { ["y"] = 2, ["x"] = 1, ["name"] = "cottages:glass_pane", ["z"] = 20, ["meta"] = { ["inventory"] = {  }, ["fields"] = {  } }, ["param2"] = 3, ["param1"] = 188 }, { ["y"] = 2, ["x"] = 1, ["name"] = "cottages:loam", ["z"] = 21, ["meta"] = { ["inventory"] = {  }, ["fields"] = {  } }, ["param2"] = 0, ["param1"] = 0 }, { ["y"] = 2, ["x"] = 1, ["name"] = "cottages:loam", ["z"] = 22, ["meta"] = { ["inventory"] = {  }, ["fields"] = {  } }, ["param2"] = 0, ["param1"] = 0 }, { ["y"] = 3, ["x"] = 1, ["name"] = "cottages:loam", ["z"] = 8, ["meta"] = { ["inventory"] = {  }, ["fields"] = {  } }, ["param2"] = 0, ["param1"] = 0 }, { ["y"] = 3, ["x"] = 1, ["name"] = "cottages:loam", ["z"] = 9, ["meta"] = { ["inventory"] = {  }, ["fields"] = {  } }, ["param2"] = 0, ["param1"] = 0 }, { ["y"] = 3, ["x"] = 1, ["name"] = "cottages:glass_pane", ["z"] = 10, ["meta"] = { ["inventory"] = {  }, ["fields"] = {  } }, ["param2"] = 3, ["param1"] = 172 }, { ["y"] = 3, ["x"] = 1, ["name"] = "cottages:loam", ["z"] = 11, ["meta"] = { ["inventory"] = {  }, ["fields"] = {  } }, ["param2"] = 0, ["param1"] = 0 }, { ["y"] = 3, ["x"] = 1, ["name"] = "cottages:glass_pane", ["z"] = 12, ["meta"] = { ["inventory"] = {  }, ["fields"] = {  } }, ["param2"] = 3, ["param1"] = 172 }, { ["y"] = 3, ["x"] = 1, ["name"] = "cottages:loam", ["z"] = 13, ["meta"] = { ["inventory"] = {  }, ["fields"] = {  } }, ["param2"] = 0, ["param1"] = 0 }, { ["y"] = 3, ["x"] = 1, ["name"] = "cottages:glass_pane", ["z"] = 14, ["meta"] = { ["inventory"] = {  }, ["fields"] = {  } }, ["param2"] = 3, ["param1"] = 172 }, { ["y"] = 3, ["x"] = 1, ["name"] = "cottages:loam", ["z"] = 15, ["meta"] = { ["inventory"] = {  }, ["fields"] = {  } }, ["param2"] = 0, ["param1"] = 0 }, { ["y"] = 3, ["x"] = 1, ["name"] = "cottages:glass_pane", ["z"] = 16, ["meta"] = { ["inventory"] = {  }, ["fields"] = {  } }, ["param2"] = 3, ["param1"] = 172 }, { ["y"] = 3, ["x"] = 1, ["name"] = "cottages:loam", ["z"] = 17, ["meta"] = { ["inventory"] = {  }, ["fields"] = {  } }, ["param2"] = 0, ["param1"] = 0 }, { ["y"] = 3, ["x"] = 1, ["name"] = "cottages:glass_pane", ["z"] = 18, ["meta"] = { ["inventory"] = {  }, ["fields"] = {  } }, ["param2"] = 3, ["param1"] = 172 }, { ["y"] = 3, ["x"] = 1, ["name"] = "cottages:loam", ["z"] = 19, ["meta"] = { ["inventory"] = {  }, ["fields"] = {  } }, ["param2"] = 0, ["param1"] = 0 }, { ["y"] = 3, ["x"] = 1, ["name"] = "cottages:glass_pane", ["z"] = 20, ["meta"] = { ["inventory"] = {  }, ["fields"] = {  } }, ["param2"] = 3, ["param1"] = 172 }, { ["y"] = 3, ["x"] = 1, ["name"] = "cottages:loam", ["z"] = 21, ["meta"] = { ["inventory"] = {  }, ["fields"] = {  } }, ["param2"] = 0, ["param1"] = 0 }, { ["y"] = 3, ["x"] = 1, ["name"] = "cottages:loam", ["z"] = 22, ["meta"] = { ["inventory"] = {  }, ["fields"] = {  } }, ["param2"] = 0, ["param1"] = 0 }, { ["y"] = 4, ["x"] = 1, ["name"] = "cottages:loam", ["z"] = 8, ["meta"] = { ["inventory"] = {  }, ["fields"] = {  } }, ["param2"] = 0, ["param1"] = 0 }, { ["y"] = 4, ["x"] = 1, ["name"] = "cottages:loam", ["z"] = 9, ["meta"] = { ["inventory"] = {  }, ["fields"] = {  } }, ["param2"] = 0, ["param1"] = 0 }, { ["y"] = 4, ["x"] = 1, ["name"] = "cottages:loam", ["z"] = 10, ["meta"] = { ["inventory"] = {  }, ["fields"] = {  } }, ["param2"] = 0, ["param1"] = 0 }, { ["y"] = 4, ["x"] = 1, ["name"] = "cottages:loam", ["z"] = 11, ["meta"] = { ["inventory"] = {  }, ["fields"] = {  } }, ["param2"] = 0, ["param1"] = 0 }, { ["y"] = 4, ["x"] = 1, ["name"] = "cottages:loam", ["z"] = 12, ["meta"] = { ["inventory"] = {  }, ["fields"] = {  } }, ["param2"] = 0, ["param1"] = 0 }, { ["y"] = 4, ["x"] = 1, ["name"] = "cottages:loam", ["z"] = 13, ["meta"] = { ["inventory"] = {  }, ["fields"] = {  } }, ["param2"] = 0, ["param1"] = 0 }, { ["y"] = 4, ["x"] = 1, ["name"] = "cottages:loam", ["z"] = 14, ["meta"] = { ["inventory"] = {  }, ["fields"] = {  } }, ["param2"] = 0, ["param1"] = 0 }, { ["y"] = 4, ["x"] = 1, ["name"] = "cottages:loam", ["z"] = 15, ["meta"] = { ["inventory"] = {  }, ["fields"] = {  } }, ["param2"] = 0, ["param1"] = 0 }, { ["y"] = 4, ["x"] = 1, ["name"] = "cottages:loam", ["z"] = 16, ["meta"] = { ["inventory"] = {  }, ["fields"] = {  } }, ["param2"] = 0, ["param1"] = 0 }, { ["y"] = 4, ["x"] = 1, ["name"] = "cottages:loam", ["z"] = 17, ["meta"] = { ["inventory"] = {  }, ["fields"] = {  } }, ["param2"] = 0, ["param1"] = 0 }, { ["y"] = 4, ["x"] = 1, ["name"] = "cottages:loam", ["z"] = 18, ["meta"] = { ["inventory"] = {  }, ["fields"] = {  } }, ["param2"] = 0, ["param1"] = 0 }, { ["y"] = 4, ["x"] = 1, ["name"] = "cottages:loam", ["z"] = 19, ["meta"] = { ["inventory"] = {  }, ["fields"] = {  } }, ["param2"] = 0, ["param1"] = 0 }, { ["y"] = 4, ["x"] = 1, ["name"] = "cottages:loam", ["z"] = 20, ["meta"] = { ["inventory"] = {  }, ["fields"] = {  } }, ["param2"] = 0, ["param1"] = 0 }, { ["y"] = 4, ["x"] = 1, ["name"] = "cottages:loam", ["z"] = 21, ["meta"] = { ["inventory"] = {  }, ["fields"] = {  } }, ["param2"] = 0, ["param1"] = 0 }, { ["y"] = 4, ["x"] = 1, ["name"] = "cottages:loam", ["z"] = 22, ["meta"] = { ["inventory"] = {  }, ["fields"] = {  } }, ["param2"] = 0, ["param1"] = 0 }, { ["y"] = 5, ["x"] = 1, ["name"] = "cottages:roof_connector_straw", ["z"] = 7, ["meta"] = { ["inventory"] = {  }, ["fields"] = {  } }, ["param2"] = 1, ["param1"] = 125 }, { ["y"] = 5, ["x"] = 1, ["name"] = "cottages:roof_connector_straw", ["z"] = 8, ["meta"] = { ["inventory"] = {  }, ["fields"] = {  } }, ["param2"] = 1, ["param1"] = 141 }, { ["y"] = 5, ["x"] = 1, ["name"] = "cottages:roof_connector_straw", ["z"] = 9, ["meta"] = { ["inventory"] = {  }, ["fields"] = {  } }, ["param2"] = 1, ["param1"] = 157 }, { ["y"] = 5, ["x"] = 1, ["name"] = "cottages:roof_connector_straw", ["z"] = 10, ["meta"] = { ["inventory"] = {  }, ["fields"] = {  } }, ["param2"] = 1, ["param1"] = 173 }, { ["y"] = 5, ["x"] = 1, ["name"] = "cottages:roof_connector_straw", ["z"] = 11, ["meta"] = { ["inventory"] = {  }, ["fields"] = {  } }, ["param2"] = 1, ["param1"] = 189 }, { ["y"] = 5, ["x"] = 1, ["name"] = "cottages:roof_connector_straw", ["z"] = 12, ["meta"] = { ["inventory"] = {  }, ["fields"] = {  } }, ["param2"] = 1, ["param1"] = 173 }, { ["y"] = 5, ["x"] = 1, ["name"] = "cottages:roof_connector_straw", ["z"] = 13, ["meta"] = { ["inventory"] = {  }, ["fields"] = {  } }, ["param2"] = 1, ["param1"] = 189 }, { ["y"] = 5, ["x"] = 1, ["name"] = "cottages:roof_connector_straw", ["z"] = 14, ["meta"] = { ["inventory"] = {  }, ["fields"] = {  } }, ["param2"] = 1, ["param1"] = 173 }, { ["y"] = 5, ["x"] = 1, ["name"] = "cottages:roof_connector_straw", ["z"] = 15, ["meta"] = { ["inventory"] = {  }, ["fields"] = {  } }, ["param2"] = 1, ["param1"] = 189 }, { ["y"] = 5, ["x"] = 1, ["name"] = "cottages:roof_connector_straw", ["z"] = 16, ["meta"] = { ["inventory"] = {  }, ["fields"] = {  } }, ["param2"] = 1, ["param1"] = 173 }, { ["y"] = 5, ["x"] = 1, ["name"] = "cottages:roof_connector_straw", ["z"] = 17, ["meta"] = { ["inventory"] = {  }, ["fields"] = {  } }, ["param2"] = 1, ["param1"] = 189 }, { ["y"] = 5, ["x"] = 1, ["name"] = "cottages:roof_connector_straw", ["z"] = 18, ["meta"] = { ["inventory"] = {  }, ["fields"] = {  } }, ["param2"] = 1, ["param1"] = 173 }, { ["y"] = 5, ["x"] = 1, ["name"] = "cottages:roof_connector_straw", ["z"] = 19, ["meta"] = { ["inventory"] = {  }, ["fields"] = {  } }, ["param2"] = 1, ["param1"] = 189 }, { ["y"] = 5, ["x"] = 1, ["name"] = "cottages:roof_connector_straw", ["z"] = 20, ["meta"] = { ["inventory"] = {  }, ["fields"] = {  } }, ["param2"] = 1, ["param1"] = 173 }, { ["y"] = 5, ["x"] = 1, ["name"] = "cottages:roof_connector_straw", ["z"] = 21, ["meta"] = { ["inventory"] = {  }, ["fields"] = {  } }, ["param2"] = 1, ["param1"] = 189 }, { ["y"] = 5, ["x"] = 1, ["name"] = "cottages:roof_connector_straw", ["z"] = 22, ["meta"] = { ["inventory"] = {  }, ["fields"] = {  } }, ["param2"] = 1, ["param1"] = 173 }, { ["y"] = 5, ["x"] = 1, ["name"] = "cottages:roof_straw", ["z"] = 23, ["meta"] = { ["inventory"] = {  }, ["fields"] = {  } }, ["param2"] = 1, ["param1"] = 157 }, { ["y"] = 0, ["x"] = 2, ["name"] = "stairs:slab_cobble", ["z"] = 0, ["meta"] = { ["inventory"] = {  }, ["fields"] = {  } }, ["param2"] = 0, ["param1"] = 109 }, { ["y"] = 0, ["x"] = 2, ["name"] = "stairs:slab_cobble", ["z"] = 1, ["meta"] = { ["inventory"] = {  }, ["fields"] = {  } }, ["param2"] = 0, ["param1"] = 125 }, { ["y"] = 0, ["x"] = 2, ["name"] = "stairs:slab_cobble", ["z"] = 2, ["meta"] = { ["inventory"] = {  }, ["fields"] = {  } }, ["param2"] = 0, ["param1"] = 141 }, { ["y"] = 0, ["x"] = 2, ["name"] = "stairs:slab_cobble", ["z"] = 3, ["meta"] = { ["inventory"] = {  }, ["fields"] = {  } }, ["param2"] = 0, ["param1"] = 157 }, { ["y"] = 0, ["x"] = 2, ["name"] = "stairs:slab_cobble", ["z"] = 4, ["meta"] = { ["inventory"] = {  }, ["fields"] = {  } }, ["param2"] = 0, ["param1"] = 141 }, { ["y"] = 0, ["x"] = 2, ["name"] = "default:cobble", ["z"] = 8, ["meta"] = { ["inventory"] = {  }, ["fields"] = {  } }, ["param2"] = 0, ["param1"] = 0 }, { ["y"] = 0, ["x"] = 2, ["name"] = "default:cobble", ["z"] = 9, ["meta"] = { ["inventory"] = {  }, ["fields"] = {  } }, ["param2"] = 0, ["param1"] = 0 }, { ["y"] = 0, ["x"] = 2, ["name"] = "stairs:slab_cobble", ["z"] = 10, ["meta"] = { ["inventory"] = {  }, ["fields"] = {  } }, ["param2"] = 0, ["param1"] = 170 }, { ["y"] = 0, ["x"] = 2, ["name"] = "stairs:slab_cobble", ["z"] = 11, ["meta"] = { ["inventory"] = {  }, ["fields"] = {  } }, ["param2"] = 0, ["param1"] = 187 }, { ["y"] = 0, ["x"] = 2, ["name"] = "stairs:slab_cobble", ["z"] = 12, ["meta"] = { ["inventory"] = {  }, ["fields"] = {  } }, ["param2"] = 0, ["param1"] = 170 }, { ["y"] = 0, ["x"] = 2, ["name"] = "stairs:slab_cobble", ["z"] = 13, ["meta"] = { ["inventory"] = {  }, ["fields"] = {  } }, ["param2"] = 0, ["param1"] = 187 }, { ["y"] = 0, ["x"] = 2, ["name"] = "stairs:slab_cobble", ["z"] = 14, ["meta"] = { ["inventory"] = {  }, ["fields"] = {  } }, ["param2"] = 0, ["param1"] = 170 }, { ["y"] = 0, ["x"] = 2, ["name"] = "stairs:slab_cobble", ["z"] = 15, ["meta"] = { ["inventory"] = {  }, ["fields"] = {  } }, ["param2"] = 0, ["param1"] = 187 }, { ["y"] = 0, ["x"] = 2, ["name"] = "stairs:slab_cobble", ["z"] = 16, ["meta"] = { ["inventory"] = {  }, ["fields"] = {  } }, ["param2"] = 0, ["param1"] = 170 }, { ["y"] = 0, ["x"] = 2, ["name"] = "stairs:slab_cobble", ["z"] = 17, ["meta"] = { ["inventory"] = {  }, ["fields"] = {  } }, ["param2"] = 0, ["param1"] = 187 }, { ["y"] = 0, ["x"] = 2, ["name"] = "stairs:slab_cobble", ["z"] = 18, ["meta"] = { ["inventory"] = {  }, ["fields"] = {  } }, ["param2"] = 0, ["param1"] = 170 }, { ["y"] = 0, ["x"] = 2, ["name"] = "stairs:slab_cobble", ["z"] = 19, ["meta"] = { ["inventory"] = {  }, ["fields"] = {  } }, ["param2"] = 0, ["param1"] = 187 }, { ["y"] = 0, ["x"] = 2, ["name"] = "stairs:slab_cobble", ["z"] = 20, ["meta"] = { ["inventory"] = {  }, ["fields"] = {  } }, ["param2"] = 0, ["param1"] = 170 }, { ["y"] = 0, ["x"] = 2, ["name"] = "stairs:slab_cobble", ["z"] = 21, ["meta"] = { ["inventory"] = {  }, ["fields"] = {  } }, ["param2"] = 0, ["param1"] = 187 }, { ["y"] = 0, ["x"] = 2, ["name"] = "stairs:slab_cobble", ["z"] = 22, ["meta"] = { ["inventory"] = {  }, ["fields"] = {  } }, ["param2"] = 0, ["param1"] = 170 }, { ["y"] = 0, ["x"] = 2, ["name"] = "default:cobble", ["z"] = 23, ["meta"] = { ["inventory"] = {  }, ["fields"] = {  } }, ["param2"] = 0, ["param1"] = 0 }, { ["y"] = 1, ["x"] = 2, ["name"] = "cottages:loam", ["z"] = 8, ["meta"] = { ["inventory"] = {  }, ["fields"] = {  } }, ["param2"] = 0, ["param1"] = 0 }, { ["y"] = 1, ["x"] = 2, ["name"] = "cottages:shelf", ["z"] = 9, ["meta"] = { ["inventory"] = { ["main"] = { "", "", "", "", "", "", "", "", "", "", "", "", "", "", "", "", "", "", "", "", "", "", "", "" } }, ["fields"] = { ["formspec"] = "size[8,8]list[current_name;main;0,0;8,3;]list[current_player;main;0,4;8,4;]", ["infotext"] = "open storage shelf" } }, ["param2"] = 2, ["param1"] = 170 }, { ["y"] = 1, ["x"] = 2, ["name"] = "cottages:loam", ["z"] = 23, ["meta"] = { ["inventory"] = {  }, ["fields"] = {  } }, ["param2"] = 0, ["param1"] = 0 }, { ["y"] = 2, ["x"] = 2, ["name"] = "cottages:loam", ["z"] = 8, ["meta"] = { ["inventory"] = {  }, ["fields"] = {  } }, ["param2"] = 0, ["param1"] = 0 }, { ["y"] = 2, ["x"] = 2, ["name"] = "cottages:shelf", ["z"] = 9, ["meta"] = { ["inventory"] = { ["main"] = { "", "", "", "", "", "", "", "", "", "", "", "", "", "", "", "", "", "", "", "", "", "", "", "" } }, ["fields"] = { ["formspec"] = "size[8,8]list[current_name;main;0,0;8,3;]list[current_player;main;0,4;8,4;]", ["infotext"] = "open storage shelf" } }, ["param2"] = 2, ["param1"] = 187 }, { ["y"] = 2, ["x"] = 2, ["name"] = "default:torch", ["z"] = 11, ["meta"] = { ["inventory"] = {  }, ["fields"] = {  } }, ["param2"] = 3, ["param1"] = 0 }, { ["y"] = 2, ["x"] = 2, ["name"] = "default:torch", ["z"] = 13, ["meta"] = { ["inventory"] = {  }, ["fields"] = {  } }, ["param2"] = 3, ["param1"] = 0 }, { ["y"] = 2, ["x"] = 2, ["name"] = "default:torch", ["z"] = 15, ["meta"] = { ["inventory"] = {  }, ["fields"] = {  } }, ["param2"] = 3, ["param1"] = 0 }, { ["y"] = 2, ["x"] = 2, ["name"] = "default:torch", ["z"] = 17, ["meta"] = { ["inventory"] = {  }, ["fields"] = {  } }, ["param2"] = 3, ["param1"] = 0 }, { ["y"] = 2, ["x"] = 2, ["name"] = "default:torch", ["z"] = 19, ["meta"] = { ["inventory"] = {  }, ["fields"] = {  } }, ["param2"] = 3, ["param1"] = 0 }, { ["y"] = 2, ["x"] = 2, ["name"] = "default:torch", ["z"] = 21, ["meta"] = { ["inventory"] = {  }, ["fields"] = {  } }, ["param2"] = 3, ["param1"] = 0 }, { ["y"] = 2, ["x"] = 2, ["name"] = "cottages:loam", ["z"] = 23, ["meta"] = { ["inventory"] = {  }, ["fields"] = {  } }, ["param2"] = 0, ["param1"] = 0 }, { ["y"] = 3, ["x"] = 2, ["name"] = "cottages:loam", ["z"] = 8, ["meta"] = { ["inventory"] = {  }, ["fields"] = {  } }, ["param2"] = 0, ["param1"] = 0 }, { ["y"] = 3, ["x"] = 2, ["name"] = "cottages:loam", ["z"] = 23, ["meta"] = { ["inventory"] = {  }, ["fields"] = {  } }, ["param2"] = 0, ["param1"] = 0 }, { ["y"] = 4, ["x"] = 2, ["name"] = "cottages:loam", ["z"] = 8, ["meta"] = { ["inventory"] = {  }, ["fields"] = {  } }, ["param2"] = 0, ["param1"] = 0 }, { ["y"] = 4, ["x"] = 2, ["name"] = "default:torch", ["z"] = 11, ["meta"] = { ["inventory"] = {  }, ["fields"] = {  } }, ["param2"] = 3, ["param1"] = 0 }, { ["y"] = 4, ["x"] = 2, ["name"] = "default:torch", ["z"] = 13, ["meta"] = { ["inventory"] = {  }, ["fields"] = {  } }, ["param2"] = 3, ["param1"] = 0 }, { ["y"] = 4, ["x"] = 2, ["name"] = "default:torch", ["z"] = 15, ["meta"] = { ["inventory"] = {  }, ["fields"] = {  } }, ["param2"] = 3, ["param1"] = 0 }, { ["y"] = 4, ["x"] = 2, ["name"] = "default:torch", ["z"] = 17, ["meta"] = { ["inventory"] = {  }, ["fields"] = {  } }, ["param2"] = 3, ["param1"] = 0 }, { ["y"] = 4, ["x"] = 2, ["name"] = "default:torch", ["z"] = 19, ["meta"] = { ["inventory"] = {  }, ["fields"] = {  } }, ["param2"] = 3, ["param1"] = 0 }, { ["y"] = 4, ["x"] = 2, ["name"] = "default:torch", ["z"] = 21, ["meta"] = { ["inventory"] = {  }, ["fields"] = {  } }, ["param2"] = 3, ["param1"] = 0 }, { ["y"] = 4, ["x"] = 2, ["name"] = "cottages:loam", ["z"] = 23, ["meta"] = { ["inventory"] = {  }, ["fields"] = {  } }, ["param2"] = 0, ["param1"] = 0 }, { ["y"] = 5, ["x"] = 2, ["name"] = "cottages:loam", ["z"] = 8, ["meta"] = { ["inventory"] = {  }, ["fields"] = {  } }, ["param2"] = 0, ["param1"] = 0 }, { ["y"] = 5, ["x"] = 2, ["name"] = "cottages:loam", ["z"] = 23, ["meta"] = { ["inventory"] = {  }, ["fields"] = {  } }, ["param2"] = 0, ["param1"] = 0 }, { ["y"] = 5, ["x"] = 2, ["name"] = "cottages:roof_straw", ["z"] = 24, ["meta"] = { ["inventory"] = {  }, ["fields"] = {  } }, ["param2"] = 1, ["param1"] = 125 }, { ["y"] = 5, ["x"] = 2, ["name"] = "cottages:roof_flat_straw", ["z"] = 25, ["meta"] = { ["inventory"] = {  }, ["fields"] = {  } }, ["param2"] = 2, ["param1"] = 109 }, { ["y"] = 6, ["x"] = 2, ["name"] = "cottages:roof_straw", ["z"] = 7, ["meta"] = { ["inventory"] = {  }, ["fields"] = {  } }, ["param2"] = 1, ["param1"] = 157 }, { ["y"] = 6, ["x"] = 2, ["name"] = "cottages:roof_connector_straw", ["z"] = 8, ["meta"] = { ["inventory"] = {  }, ["fields"] = {  } }, ["param2"] = 1, ["param1"] = 141 }, { ["y"] = 6, ["x"] = 2, ["name"] = "cottages:roof_straw", ["z"] = 9, ["meta"] = { ["inventory"] = {  }, ["fields"] = {  } }, ["param2"] = 1, ["param1"] = 157 }, { ["y"] = 6, ["x"] = 2, ["name"] = "cottages:roof_straw", ["z"] = 10, ["meta"] = { ["inventory"] = {  }, ["fields"] = {  } }, ["param2"] = 1, ["param1"] = 173 }, { ["y"] = 6, ["x"] = 2, ["name"] = "cottages:roof_straw", ["z"] = 11, ["meta"] = { ["inventory"] = {  }, ["fields"] = {  } }, ["param2"] = 1, ["param1"] = 189 }, { ["y"] = 6, ["x"] = 2, ["name"] = "cottages:roof_straw", ["z"] = 12, ["meta"] = { ["inventory"] = {  }, ["fields"] = {  } }, ["param2"] = 1, ["param1"] = 173 }, { ["y"] = 6, ["x"] = 2, ["name"] = "cottages:roof_straw", ["z"] = 13, ["meta"] = { ["inventory"] = {  }, ["fields"] = {  } }, ["param2"] = 1, ["param1"] = 189 }, { ["y"] = 6, ["x"] = 2, ["name"] = "cottages:roof_straw", ["z"] = 14, ["meta"] = { ["inventory"] = {  }, ["fields"] = {  } }, ["param2"] = 1, ["param1"] = 173 }, { ["y"] = 6, ["x"] = 2, ["name"] = "cottages:roof_straw", ["z"] = 15, ["meta"] = { ["inventory"] = {  }, ["fields"] = {  } }, ["param2"] = 1, ["param1"] = 189 }, { ["y"] = 6, ["x"] = 2, ["name"] = "cottages:roof_straw", ["z"] = 16, ["meta"] = { ["inventory"] = {  }, ["fields"] = {  } }, ["param2"] = 1, ["param1"] = 173 }, { ["y"] = 6, ["x"] = 2, ["name"] = "cottages:roof_straw", ["z"] = 17, ["meta"] = { ["inventory"] = {  }, ["fields"] = {  } }, ["param2"] = 1, ["param1"] = 189 }, { ["y"] = 6, ["x"] = 2, ["name"] = "cottages:roof_straw", ["z"] = 18, ["meta"] = { ["inventory"] = {  }, ["fields"] = {  } }, ["param2"] = 1, ["param1"] = 173 }, { ["y"] = 6, ["x"] = 2, ["name"] = "cottages:roof_straw", ["z"] = 19, ["meta"] = { ["inventory"] = {  }, ["fields"] = {  } }, ["param2"] = 1, ["param1"] = 189 }, { ["y"] = 6, ["x"] = 2, ["name"] = "cottages:roof_straw", ["z"] = 20, ["meta"] = { ["inventory"] = {  }, ["fields"] = {  } }, ["param2"] = 1, ["param1"] = 173 }, { ["y"] = 6, ["x"] = 2, ["name"] = "cottages:roof_straw", ["z"] = 21, ["meta"] = { ["inventory"] = {  }, ["fields"] = {  } }, ["param2"] = 1, ["param1"] = 189 }, { ["y"] = 6, ["x"] = 2, ["name"] = "cottages:roof_straw", ["z"] = 22, ["meta"] = { ["inventory"] = {  }, ["fields"] = {  } }, ["param2"] = 1, ["param1"] = 173 }, { ["y"] = 6, ["x"] = 2, ["name"] = "cottages:roof_connector_straw", ["z"] = 23, ["meta"] = { ["inventory"] = {  }, ["fields"] = {  } }, ["param2"] = 1, ["param1"] = 157 }, { ["y"] = 12, ["x"] = 2, ["name"] = "cottages:roof_flat_straw", ["z"] = 3, ["meta"] = { ["inventory"] = {  }, ["fields"] = {  } }, ["param2"] = 1, ["param1"] = 125 }, { ["y"] = 12, ["x"] = 2, ["name"] = "cottages:roof_straw", ["z"] = 4, ["meta"] = { ["inventory"] = {  }, ["fields"] = {  } }, ["param2"] = 1, ["param1"] = 141 }, { ["y"] = 12, ["x"] = 2, ["name"] = "cottages:roof_straw", ["z"] = 5, ["meta"] = { ["inventory"] = {  }, ["fields"] = {  } }, ["param2"] = 1, ["param1"] = 157 }, { ["y"] = 12, ["x"] = 2, ["name"] = "cottages:roof_straw", ["z"] = 6, ["meta"] = { ["inventory"] = {  }, ["fields"] = {  } }, ["param2"] = 1, ["param1"] = 141 }, { ["y"] = 12, ["x"] = 2, ["name"] = "cottages:roof_straw", ["z"] = 7, ["meta"] = { ["inventory"] = {  }, ["fields"] = {  } }, ["param2"] = 1, ["param1"] = 141 }, { ["y"] = 12, ["x"] = 2, ["name"] = "cottages:roof_straw", ["z"] = 8, ["meta"] = { ["inventory"] = {  }, ["fields"] = {  } }, ["param2"] = 1, ["param1"] = 157 }, { ["y"] = 12, ["x"] = 2, ["name"] = "cottages:roof_straw", ["z"] = 9, ["meta"] = { ["inventory"] = {  }, ["fields"] = {  } }, ["param2"] = 1, ["param1"] = 141 }, { ["y"] = 12, ["x"] = 2, ["name"] = "cottages:roof_flat_straw", ["z"] = 10, ["meta"] = { ["inventory"] = {  }, ["fields"] = {  } }, ["param2"] = 1, ["param1"] = 125 }, { ["y"] = 0, ["x"] = 3, ["name"] = "stairs:slab_cobble", ["z"] = 0, ["meta"] = { ["inventory"] = {  }, ["fields"] = {  } }, ["param2"] = 0, ["param1"] = 125 }, { ["y"] = 0, ["x"] = 3, ["name"] = "stairs:slab_cobble", ["z"] = 1, ["meta"] = { ["inventory"] = {  }, ["fields"] = {  } }, ["param2"] = 0, ["param1"] = 141 }, { ["y"] = 0, ["x"] = 3, ["name"] = "stairs:slab_cobble", ["z"] = 2, ["meta"] = { ["inventory"] = {  }, ["fields"] = {  } }, ["param2"] = 0, ["param1"] = 157 }, { ["y"] = 0, ["x"] = 3, ["name"] = "stairs:slab_cobble", ["z"] = 3, ["meta"] = { ["inventory"] = {  }, ["fields"] = {  } }, ["param2"] = 0, ["param1"] = 172 }, { ["y"] = 0, ["x"] = 3, ["name"] = "default:cobble", ["z"] = 4, ["meta"] = { ["inventory"] = {  }, ["fields"] = {  } }, ["param2"] = 0, ["param1"] = 0 }, { ["y"] = 0, ["x"] = 3, ["name"] = "default:cobble", ["z"] = 5, ["meta"] = { ["inventory"] = {  }, ["fields"] = {  } }, ["param2"] = 0, ["param1"] = 0 }, { ["y"] = 0, ["x"] = 3, ["name"] = "default:cobble", ["z"] = 6, ["meta"] = { ["inventory"] = {  }, ["fields"] = {  } }, ["param2"] = 0, ["param1"] = 0 }, { ["y"] = 0, ["x"] = 3, ["name"] = "default:cobble", ["z"] = 7, ["meta"] = { ["inventory"] = {  }, ["fields"] = {  } }, ["param2"] = 0, ["param1"] = 0 }, { ["y"] = 0, ["x"] = 3, ["name"] = "default:cobble", ["z"] = 8, ["meta"] = { ["inventory"] = {  }, ["fields"] = {  } }, ["param2"] = 0, ["param1"] = 0 }, { ["y"] = 0, ["x"] = 3, ["name"] = "default:cobble", ["z"] = 9, ["meta"] = { ["inventory"] = {  }, ["fields"] = {  } }, ["param2"] = 0, ["param1"] = 0 }, { ["y"] = 0, ["x"] = 3, ["name"] = "default:cobble", ["z"] = 10, ["meta"] = { ["inventory"] = {  }, ["fields"] = {  } }, ["param2"] = 0, ["param1"] = 0 }, { ["y"] = 0, ["x"] = 3, ["name"] = "default:cobble", ["z"] = 11, ["meta"] = { ["inventory"] = {  }, ["fields"] = {  } }, ["param2"] = 0, ["param1"] = 0 }, { ["y"] = 0, ["x"] = 3, ["name"] = "default:cobble", ["z"] = 12, ["meta"] = { ["inventory"] = {  }, ["fields"] = {  } }, ["param2"] = 0, ["param1"] = 0 }, { ["y"] = 0, ["x"] = 3, ["name"] = "default:cobble", ["z"] = 13, ["meta"] = { ["inventory"] = {  }, ["fields"] = {  } }, ["param2"] = 0, ["param1"] = 0 }, { ["y"] = 0, ["x"] = 3, ["name"] = "default:cobble", ["z"] = 14, ["meta"] = { ["inventory"] = {  }, ["fields"] = {  } }, ["param2"] = 0, ["param1"] = 0 }, { ["y"] = 0, ["x"] = 3, ["name"] = "default:cobble", ["z"] = 15, ["meta"] = { ["inventory"] = {  }, ["fields"] = {  } }, ["param2"] = 0, ["param1"] = 0 }, { ["y"] = 0, ["x"] = 3, ["name"] = "default:cobble", ["z"] = 16, ["meta"] = { ["inventory"] = {  }, ["fields"] = {  } }, ["param2"] = 0, ["param1"] = 0 }, { ["y"] = 0, ["x"] = 3, ["name"] = "default:cobble", ["z"] = 17, ["meta"] = { ["inventory"] = {  }, ["fields"] = {  } }, ["param2"] = 0, ["param1"] = 0 }, { ["y"] = 0, ["x"] = 3, ["name"] = "default:cobble", ["z"] = 18, ["meta"] = { ["inventory"] = {  }, ["fields"] = {  } }, ["param2"] = 0, ["param1"] = 0 }, { ["y"] = 0, ["x"] = 3, ["name"] = "default:cobble", ["z"] = 19, ["meta"] = { ["inventory"] = {  }, ["fields"] = {  } }, ["param2"] = 0, ["param1"] = 0 }, { ["y"] = 0, ["x"] = 3, ["name"] = "stairs:slab_cobble", ["z"] = 20, ["meta"] = { ["inventory"] = {  }, ["fields"] = {  } }, ["param2"] = 0, ["param1"] = 153 }, { ["y"] = 0, ["x"] = 3, ["name"] = "stairs:slab_cobble", ["z"] = 21, ["meta"] = { ["inventory"] = {  }, ["fields"] = {  } }, ["param2"] = 0, ["param1"] = 170 }, { ["y"] = 0, ["x"] = 3, ["name"] = "stairs:slab_cobble", ["z"] = 22, ["meta"] = { ["inventory"] = {  }, ["fields"] = {  } }, ["param2"] = 0, ["param1"] = 153 }, { ["y"] = 0, ["x"] = 3, ["name"] = "default:cobble", ["z"] = 23, ["meta"] = { ["inventory"] = {  }, ["fields"] = {  } }, ["param2"] = 0, ["param1"] = 0 }, { ["y"] = 0, ["x"] = 3, ["name"] = "default:cobble", ["z"] = 24, ["meta"] = { ["inventory"] = {  }, ["fields"] = {  } }, ["param2"] = 0, ["param1"] = 0 }, { ["y"] = 1, ["x"] = 3, ["name"] = "default:clay", ["z"] = 4, ["meta"] = { ["inventory"] = {  }, ["fields"] = {  } }, ["param2"] = 0, ["param1"] = 0 }, { ["y"] = 1, ["x"] = 3, ["name"] = "default:clay", ["z"] = 5, ["meta"] = { ["inventory"] = {  }, ["fields"] = {  } }, ["param2"] = 0, ["param1"] = 0 }, { ["y"] = 1, ["x"] = 3, ["name"] = "cottages:loam", ["z"] = 6, ["meta"] = { ["inventory"] = {  }, ["fields"] = {  } }, ["param2"] = 0, ["param1"] = 0 }, { ["y"] = 1, ["x"] = 3, ["name"] = "cottages:loam", ["z"] = 7, ["meta"] = { ["inventory"] = {  }, ["fields"] = {  } }, ["param2"] = 0, ["param1"] = 0 }, { ["y"] = 1, ["x"] = 3, ["name"] = "default:clay", ["z"] = 8, ["meta"] = { ["inventory"] = {  }, ["fields"] = {  } }, ["param2"] = 0, ["param1"] = 0 }, { ["y"] = 1, ["x"] = 3, ["name"] = "default:clay", ["z"] = 9, ["meta"] = { ["inventory"] = {  }, ["fields"] = {  } }, ["param2"] = 0, ["param1"] = 0 }, { ["y"] = 1, ["x"] = 3, ["name"] = "cottages:bench", ["z"] = 10, ["meta"] = { ["inventory"] = {  }, ["fields"] = {  } }, ["param2"] = 2, ["param1"] = 187 }, { ["y"] = 1, ["x"] = 3, ["name"] = "default:fence_wood", ["z"] = 11, ["meta"] = { ["inventory"] = {  }, ["fields"] = {  } }, ["param2"] = 0, ["param1"] = 187 }, { ["y"] = 1, ["x"] = 3, ["name"] = "cottages:bench", ["z"] = 12, ["meta"] = { ["inventory"] = {  }, ["fields"] = {  } }, ["param2"] = 2, ["param1"] = 170 }, { ["y"] = 1, ["x"] = 3, ["name"] = "default:fence_wood", ["z"] = 13, ["meta"] = { ["inventory"] = {  }, ["fields"] = {  } }, ["param2"] = 0, ["param1"] = 187 }, { ["y"] = 1, ["x"] = 3, ["name"] = "cottages:bench", ["z"] = 14, ["meta"] = { ["inventory"] = {  }, ["fields"] = {  } }, ["param2"] = 2, ["param1"] = 170 }, { ["y"] = 1, ["x"] = 3, ["name"] = "default:fence_wood", ["z"] = 15, ["meta"] = { ["inventory"] = {  }, ["fields"] = {  } }, ["param2"] = 0, ["param1"] = 187 }, { ["y"] = 1, ["x"] = 3, ["name"] = "cottages:bench", ["z"] = 16, ["meta"] = { ["inventory"] = {  }, ["fields"] = {  } }, ["param2"] = 2, ["param1"] = 170 }, { ["y"] = 1, ["x"] = 3, ["name"] = "default:fence_wood", ["z"] = 17, ["meta"] = { ["inventory"] = {  }, ["fields"] = {  } }, ["param2"] = 0, ["param1"] = 187 }, { ["y"] = 1, ["x"] = 3, ["name"] = "cottages:bench", ["z"] = 18, ["meta"] = { ["inventory"] = {  }, ["fields"] = {  } }, ["param2"] = 2, ["param1"] = 170 }, { ["y"] = 1, ["x"] = 3, ["name"] = "default:fence_wood", ["z"] = 19, ["meta"] = { ["inventory"] = {  }, ["fields"] = {  } }, ["param2"] = 0, ["param1"] = 187 }, { ["y"] = 1, ["x"] = 3, ["name"] = "cottages:loam", ["z"] = 24, ["meta"] = { ["inventory"] = {  }, ["fields"] = {  } }, ["param2"] = 0, ["param1"] = 0 }, { ["y"] = 2, ["x"] = 3, ["name"] = "default:clay", ["z"] = 4, ["meta"] = { ["inventory"] = {  }, ["fields"] = {  } }, ["param2"] = 0, ["param1"] = 0 }, { ["y"] = 2, ["x"] = 3, ["name"] = "cottages:loam", ["z"] = 5, ["meta"] = { ["inventory"] = {  }, ["fields"] = {  } }, ["param2"] = 0, ["param1"] = 0 }, { ["y"] = 2, ["x"] = 3, ["name"] = "cottages:loam", ["z"] = 6, ["meta"] = { ["inventory"] = {  }, ["fields"] = {  } }, ["param2"] = 0, ["param1"] = 0 }, { ["y"] = 2, ["x"] = 3, ["name"] = "cottages:loam", ["z"] = 7, ["meta"] = { ["inventory"] = {  }, ["fields"] = {  } }, ["param2"] = 0, ["param1"] = 0 }, { ["y"] = 2, ["x"] = 3, ["name"] = "cottages:loam", ["z"] = 8, ["meta"] = { ["inventory"] = {  }, ["fields"] = {  } }, ["param2"] = 0, ["param1"] = 0 }, { ["y"] = 2, ["x"] = 3, ["name"] = "default:clay", ["z"] = 9, ["meta"] = { ["inventory"] = {  }, ["fields"] = {  } }, ["param2"] = 0, ["param1"] = 0 }, { ["y"] = 2, ["x"] = 3, ["name"] = "cottages:loam", ["z"] = 24, ["meta"] = { ["inventory"] = {  }, ["fields"] = {  } }, ["param2"] = 0, ["param1"] = 0 }, { ["y"] = 3, ["x"] = 3, ["name"] = "default:clay", ["z"] = 4, ["meta"] = { ["inventory"] = {  }, ["fields"] = {  } }, ["param2"] = 0, ["param1"] = 0 }, { ["y"] = 3, ["x"] = 3, ["name"] = "default:clay", ["z"] = 5, ["meta"] = { ["inventory"] = {  }, ["fields"] = {  } }, ["param2"] = 0, ["param1"] = 0 }, { ["y"] = 3, ["x"] = 3, ["name"] = "cottages:glass_pane", ["z"] = 6, ["meta"] = { ["inventory"] = {  }, ["fields"] = {  } }, ["param2"] = 1, ["param1"] = 172 }, { ["y"] = 3, ["x"] = 3, ["name"] = "cottages:loam", ["z"] = 7, ["meta"] = { ["inventory"] = {  }, ["fields"] = {  } }, ["param2"] = 0, ["param1"] = 0 }, { ["y"] = 3, ["x"] = 3, ["name"] = "default:clay", ["z"] = 8, ["meta"] = { ["inventory"] = {  }, ["fields"] = {  } }, ["param2"] = 0, ["param1"] = 0 }, { ["y"] = 3, ["x"] = 3, ["name"] = "default:clay", ["z"] = 9, ["meta"] = { ["inventory"] = {  }, ["fields"] = {  } }, ["param2"] = 0, ["param1"] = 0 }, { ["y"] = 3, ["x"] = 3, ["name"] = "default:torch", ["z"] = 23, ["meta"] = { ["inventory"] = {  }, ["fields"] = {  } }, ["param2"] = 4, ["param1"] = 0 }, { ["y"] = 3, ["x"] = 3, ["name"] = "cottages:loam", ["z"] = 24, ["meta"] = { ["inventory"] = {  }, ["fields"] = {  } }, ["param2"] = 0, ["param1"] = 0 }, { ["y"] = 4, ["x"] = 3, ["name"] = "default:clay", ["z"] = 4, ["meta"] = { ["inventory"] = {  }, ["fields"] = {  } }, ["param2"] = 0, ["param1"] = 0 }, { ["y"] = 4, ["x"] = 3, ["name"] = "cottages:loam", ["z"] = 5, ["meta"] = { ["inventory"] = {  }, ["fields"] = {  } }, ["param2"] = 0, ["param1"] = 0 }, { ["y"] = 4, ["x"] = 3, ["name"] = "cottages:glass_pane", ["z"] = 6, ["meta"] = { ["inventory"] = {  }, ["fields"] = {  } }, ["param2"] = 1, ["param1"] = 188 }, { ["y"] = 4, ["x"] = 3, ["name"] = "cottages:loam", ["z"] = 7, ["meta"] = { ["inventory"] = {  }, ["fields"] = {  } }, ["param2"] = 0, ["param1"] = 0 }, { ["y"] = 4, ["x"] = 3, ["name"] = "cottages:loam", ["z"] = 8, ["meta"] = { ["inventory"] = {  }, ["fields"] = {  } }, ["param2"] = 0, ["param1"] = 0 }, { ["y"] = 4, ["x"] = 3, ["name"] = "default:clay", ["z"] = 9, ["meta"] = { ["inventory"] = {  }, ["fields"] = {  } }, ["param2"] = 0, ["param1"] = 0 }, { ["y"] = 4, ["x"] = 3, ["name"] = "cottages:loam", ["z"] = 24, ["meta"] = { ["inventory"] = {  }, ["fields"] = {  } }, ["param2"] = 0, ["param1"] = 0 }, { ["y"] = 5, ["x"] = 3, ["name"] = "default:clay", ["z"] = 4, ["meta"] = { ["inventory"] = {  }, ["fields"] = {  } }, ["param2"] = 0, ["param1"] = 0 }, { ["y"] = 5, ["x"] = 3, ["name"] = "default:clay", ["z"] = 5, ["meta"] = { ["inventory"] = {  }, ["fields"] = {  } }, ["param2"] = 0, ["param1"] = 0 }, { ["y"] = 5, ["x"] = 3, ["name"] = "cottages:loam", ["z"] = 6, ["meta"] = { ["inventory"] = {  }, ["fields"] = {  } }, ["param2"] = 0, ["param1"] = 0 }, { ["y"] = 5, ["x"] = 3, ["name"] = "cottages:loam", ["z"] = 7, ["meta"] = { ["inventory"] = {  }, ["fields"] = {  } }, ["param2"] = 0, ["param1"] = 0 }, { ["y"] = 5, ["x"] = 3, ["name"] = "default:clay", ["z"] = 8, ["meta"] = { ["inventory"] = {  }, ["fields"] = {  } }, ["param2"] = 0, ["param1"] = 0 }, { ["y"] = 5, ["x"] = 3, ["name"] = "default:clay", ["z"] = 9, ["meta"] = { ["inventory"] = {  }, ["fields"] = {  } }, ["param2"] = 0, ["param1"] = 0 }, { ["y"] = 5, ["x"] = 3, ["name"] = "cottages:loam", ["z"] = 23, ["meta"] = { ["inventory"] = {  }, ["fields"] = {  } }, ["param2"] = 0, ["param1"] = 0 }, { ["y"] = 5, ["x"] = 3, ["name"] = "cottages:loam", ["z"] = 24, ["meta"] = { ["inventory"] = {  }, ["fields"] = {  } }, ["param2"] = 0, ["param1"] = 0 }, { ["y"] = 5, ["x"] = 3, ["name"] = "cottages:roof_straw", ["z"] = 25, ["meta"] = { ["inventory"] = {  }, ["fields"] = {  } }, ["param2"] = 2, ["param1"] = 109 }, { ["y"] = 6, ["x"] = 3, ["name"] = "default:clay", ["z"] = 4, ["meta"] = { ["inventory"] = {  }, ["fields"] = {  } }, ["param2"] = 0, ["param1"] = 0 }, { ["y"] = 6, ["x"] = 3, ["name"] = "cottages:loam", ["z"] = 5, ["meta"] = { ["inventory"] = {  }, ["fields"] = {  } }, ["param2"] = 0, ["param1"] = 0 }, { ["y"] = 6, ["x"] = 3, ["name"] = "cottages:loam", ["z"] = 6, ["meta"] = { ["inventory"] = {  }, ["fields"] = {  } }, ["param2"] = 0, ["param1"] = 0 }, { ["y"] = 6, ["x"] = 3, ["name"] = "cottages:glass_pane", ["z"] = 7, ["meta"] = { ["inventory"] = {  }, ["fields"] = {  } }, ["param2"] = 3, ["param1"] = 172 }, { ["y"] = 6, ["x"] = 3, ["name"] = "cottages:loam", ["z"] = 8, ["meta"] = { ["inventory"] = {  }, ["fields"] = {  } }, ["param2"] = 0, ["param1"] = 0 }, { ["y"] = 6, ["x"] = 3, ["name"] = "default:clay", ["z"] = 9, ["meta"] = { ["inventory"] = {  }, ["fields"] = {  } }, ["param2"] = 0, ["param1"] = 0 }, { ["y"] = 6, ["x"] = 3, ["name"] = "cottages:loam", ["z"] = 23, ["meta"] = { ["inventory"] = {  }, ["fields"] = {  } }, ["param2"] = 0, ["param1"] = 0 }, { ["y"] = 6, ["x"] = 3, ["name"] = "cottages:roof_connector_straw", ["z"] = 24, ["meta"] = { ["inventory"] = {  }, ["fields"] = {  } }, ["param2"] = 2, ["param1"] = 125 }, { ["y"] = 7, ["x"] = 3, ["name"] = "default:clay", ["z"] = 4, ["meta"] = { ["inventory"] = {  }, ["fields"] = {  } }, ["param2"] = 0, ["param1"] = 0 }, { ["y"] = 7, ["x"] = 3, ["name"] = "default:clay", ["z"] = 5, ["meta"] = { ["inventory"] = {  }, ["fields"] = {  } }, ["param2"] = 0, ["param1"] = 0 }, { ["y"] = 7, ["x"] = 3, ["name"] = "cottages:loam", ["z"] = 6, ["meta"] = { ["inventory"] = {  }, ["fields"] = {  } }, ["param2"] = 0, ["param1"] = 0 }, { ["y"] = 7, ["x"] = 3, ["name"] = "cottages:glass_pane", ["z"] = 7, ["meta"] = { ["inventory"] = {  }, ["fields"] = {  } }, ["param2"] = 3, ["param1"] = 188 }, { ["y"] = 7, ["x"] = 3, ["name"] = "default:clay", ["z"] = 8, ["meta"] = { ["inventory"] = {  }, ["fields"] = {  } }, ["param2"] = 0, ["param1"] = 0 }, { ["y"] = 7, ["x"] = 3, ["name"] = "default:clay", ["z"] = 9, ["meta"] = { ["inventory"] = {  }, ["fields"] = {  } }, ["param2"] = 0, ["param1"] = 0 }, { ["y"] = 7, ["x"] = 3, ["name"] = "cottages:roof_straw", ["z"] = 10, ["meta"] = { ["inventory"] = {  }, ["fields"] = {  } }, ["param2"] = 1, ["param1"] = 172 }, { ["y"] = 7, ["x"] = 3, ["name"] = "cottages:roof_straw", ["z"] = 11, ["meta"] = { ["inventory"] = {  }, ["fields"] = {  } }, ["param2"] = 1, ["param1"] = 157 }, { ["y"] = 7, ["x"] = 3, ["name"] = "cottages:roof_straw", ["z"] = 12, ["meta"] = { ["inventory"] = {  }, ["fields"] = {  } }, ["param2"] = 1, ["param1"] = 173 }, { ["y"] = 7, ["x"] = 3, ["name"] = "cottages:roof_straw", ["z"] = 13, ["meta"] = { ["inventory"] = {  }, ["fields"] = {  } }, ["param2"] = 1, ["param1"] = 157 }, { ["y"] = 7, ["x"] = 3, ["name"] = "cottages:roof_straw", ["z"] = 14, ["meta"] = { ["inventory"] = {  }, ["fields"] = {  } }, ["param2"] = 1, ["param1"] = 157 }, { ["y"] = 7, ["x"] = 3, ["name"] = "cottages:roof_straw", ["z"] = 15, ["meta"] = { ["inventory"] = {  }, ["fields"] = {  } }, ["param2"] = 1, ["param1"] = 157 }, { ["y"] = 7, ["x"] = 3, ["name"] = "cottages:roof_straw", ["z"] = 16, ["meta"] = { ["inventory"] = {  }, ["fields"] = {  } }, ["param2"] = 1, ["param1"] = 173 }, { ["y"] = 7, ["x"] = 3, ["name"] = "cottages:roof_straw", ["z"] = 17, ["meta"] = { ["inventory"] = {  }, ["fields"] = {  } }, ["param2"] = 1, ["param1"] = 157 }, { ["y"] = 7, ["x"] = 3, ["name"] = "cottages:roof_straw", ["z"] = 18, ["meta"] = { ["inventory"] = {  }, ["fields"] = {  } }, ["param2"] = 1, ["param1"] = 141 }, { ["y"] = 7, ["x"] = 3, ["name"] = "cottages:roof_straw", ["z"] = 19, ["meta"] = { ["inventory"] = {  }, ["fields"] = {  } }, ["param2"] = 1, ["param1"] = 157 }, { ["y"] = 7, ["x"] = 3, ["name"] = "cottages:roof_straw", ["z"] = 20, ["meta"] = { ["inventory"] = {  }, ["fields"] = {  } }, ["param2"] = 1, ["param1"] = 173 }, { ["y"] = 7, ["x"] = 3, ["name"] = "cottages:roof_straw", ["z"] = 21, ["meta"] = { ["inventory"] = {  }, ["fields"] = {  } }, ["param2"] = 1, ["param1"] = 157 }, { ["y"] = 7, ["x"] = 3, ["name"] = "cottages:roof_straw", ["z"] = 22, ["meta"] = { ["inventory"] = {  }, ["fields"] = {  } }, ["param2"] = 1, ["param1"] = 173 }, { ["y"] = 7, ["x"] = 3, ["name"] = "cottages:roof_connector_straw", ["z"] = 23, ["meta"] = { ["inventory"] = {  }, ["fields"] = {  } }, ["param2"] = 1, ["param1"] = 157 }, { ["y"] = 8, ["x"] = 3, ["name"] = "default:clay", ["z"] = 4, ["meta"] = { ["inventory"] = {  }, ["fields"] = {  } }, ["param2"] = 0, ["param1"] = 0 }, { ["y"] = 8, ["x"] = 3, ["name"] = "cottages:loam", ["z"] = 5, ["meta"] = { ["inventory"] = {  }, ["fields"] = {  } }, ["param2"] = 0, ["param1"] = 0 }, { ["y"] = 8, ["x"] = 3, ["name"] = "cottages:loam", ["z"] = 6, ["meta"] = { ["inventory"] = {  }, ["fields"] = {  } }, ["param2"] = 0, ["param1"] = 0 }, { ["y"] = 8, ["x"] = 3, ["name"] = "cottages:loam", ["z"] = 7, ["meta"] = { ["inventory"] = {  }, ["fields"] = {  } }, ["param2"] = 0, ["param1"] = 0 }, { ["y"] = 8, ["x"] = 3, ["name"] = "cottages:loam", ["z"] = 8, ["meta"] = { ["inventory"] = {  }, ["fields"] = {  } }, ["param2"] = 0, ["param1"] = 0 }, { ["y"] = 8, ["x"] = 3, ["name"] = "default:clay", ["z"] = 9, ["meta"] = { ["inventory"] = {  }, ["fields"] = {  } }, ["param2"] = 0, ["param1"] = 0 }, { ["y"] = 9, ["x"] = 3, ["name"] = "default:clay", ["z"] = 4, ["meta"] = { ["inventory"] = {  }, ["fields"] = {  } }, ["param2"] = 0, ["param1"] = 0 }, { ["y"] = 9, ["x"] = 3, ["name"] = "default:clay", ["z"] = 5, ["meta"] = { ["inventory"] = {  }, ["fields"] = {  } }, ["param2"] = 0, ["param1"] = 0 }, { ["y"] = 9, ["x"] = 3, ["name"] = "cottages:glass_pane", ["z"] = 6, ["meta"] = { ["inventory"] = {  }, ["fields"] = {  } }, ["param2"] = 3, ["param1"] = 172 }, { ["y"] = 9, ["x"] = 3, ["name"] = "cottages:loam", ["z"] = 7, ["meta"] = { ["inventory"] = {  }, ["fields"] = {  } }, ["param2"] = 0, ["param1"] = 0 }, { ["y"] = 9, ["x"] = 3, ["name"] = "default:clay", ["z"] = 8, ["meta"] = { ["inventory"] = {  }, ["fields"] = {  } }, ["param2"] = 0, ["param1"] = 0 }, { ["y"] = 9, ["x"] = 3, ["name"] = "default:clay", ["z"] = 9, ["meta"] = { ["inventory"] = {  }, ["fields"] = {  } }, ["param2"] = 0, ["param1"] = 0 }, { ["y"] = 10, ["x"] = 3, ["name"] = "default:clay", ["z"] = 4, ["meta"] = { ["inventory"] = {  }, ["fields"] = {  } }, ["param2"] = 0, ["param1"] = 0 }, { ["y"] = 10, ["x"] = 3, ["name"] = "cottages:loam", ["z"] = 5, ["meta"] = { ["inventory"] = {  }, ["fields"] = {  } }, ["param2"] = 0, ["param1"] = 0 }, { ["y"] = 10, ["x"] = 3, ["name"] = "cottages:glass_pane", ["z"] = 6, ["meta"] = { ["inventory"] = {  }, ["fields"] = {  } }, ["param2"] = 3, ["param1"] = 188 }, { ["y"] = 10, ["x"] = 3, ["name"] = "cottages:loam", ["z"] = 7, ["meta"] = { ["inventory"] = {  }, ["fields"] = {  } }, ["param2"] = 0, ["param1"] = 0 }, { ["y"] = 10, ["x"] = 3, ["name"] = "cottages:loam", ["z"] = 8, ["meta"] = { ["inventory"] = {  }, ["fields"] = {  } }, ["param2"] = 0, ["param1"] = 0 }, { ["y"] = 10, ["x"] = 3, ["name"] = "default:clay", ["z"] = 9, ["meta"] = { ["inventory"] = {  }, ["fields"] = {  } }, ["param2"] = 0, ["param1"] = 0 }, { ["y"] = 11, ["x"] = 3, ["name"] = "default:clay", ["z"] = 4, ["meta"] = { ["inventory"] = {  }, ["fields"] = {  } }, ["param2"] = 0, ["param1"] = 0 }, { ["y"] = 11, ["x"] = 3, ["name"] = "default:clay", ["z"] = 5, ["meta"] = { ["inventory"] = {  }, ["fields"] = {  } }, ["param2"] = 0, ["param1"] = 0 }, { ["y"] = 11, ["x"] = 3, ["name"] = "cottages:loam", ["z"] = 6, ["meta"] = { ["inventory"] = {  }, ["fields"] = {  } }, ["param2"] = 0, ["param1"] = 0 }, { ["y"] = 11, ["x"] = 3, ["name"] = "cottages:loam", ["z"] = 7, ["meta"] = { ["inventory"] = {  }, ["fields"] = {  } }, ["param2"] = 0, ["param1"] = 0 }, { ["y"] = 11, ["x"] = 3, ["name"] = "default:clay", ["z"] = 8, ["meta"] = { ["inventory"] = {  }, ["fields"] = {  } }, ["param2"] = 0, ["param1"] = 0 }, { ["y"] = 11, ["x"] = 3, ["name"] = "default:clay", ["z"] = 9, ["meta"] = { ["inventory"] = {  }, ["fields"] = {  } }, ["param2"] = 0, ["param1"] = 0 }, { ["y"] = 12, ["x"] = 3, ["name"] = "cottages:roof_straw", ["z"] = 3, ["meta"] = { ["inventory"] = {  }, ["fields"] = {  } }, ["param2"] = 0, ["param1"] = 141 }, { ["y"] = 12, ["x"] = 3, ["name"] = "default:clay", ["z"] = 4, ["meta"] = { ["inventory"] = {  }, ["fields"] = {  } }, ["param2"] = 0, ["param1"] = 0 }, { ["y"] = 12, ["x"] = 3, ["name"] = "cottages:loam", ["z"] = 5, ["meta"] = { ["inventory"] = {  }, ["fields"] = {  } }, ["param2"] = 0, ["param1"] = 0 }, { ["y"] = 12, ["x"] = 3, ["name"] = "cottages:loam", ["z"] = 6, ["meta"] = { ["inventory"] = {  }, ["fields"] = {  } }, ["param2"] = 0, ["param1"] = 0 }, { ["y"] = 12, ["x"] = 3, ["name"] = "cottages:loam", ["z"] = 7, ["meta"] = { ["inventory"] = {  }, ["fields"] = {  } }, ["param2"] = 0, ["param1"] = 0 }, { ["y"] = 12, ["x"] = 3, ["name"] = "cottages:loam", ["z"] = 8, ["meta"] = { ["inventory"] = {  }, ["fields"] = {  } }, ["param2"] = 0, ["param1"] = 0 }, { ["y"] = 12, ["x"] = 3, ["name"] = "default:clay", ["z"] = 9, ["meta"] = { ["inventory"] = {  }, ["fields"] = {  } }, ["param2"] = 0, ["param1"] = 0 }, { ["y"] = 12, ["x"] = 3, ["name"] = "cottages:roof_straw", ["z"] = 10, ["meta"] = { ["inventory"] = {  }, ["fields"] = {  } }, ["param2"] = 2, ["param1"] = 141 }, { ["y"] = 13, ["x"] = 3, ["name"] = "cottages:roof_flat_straw", ["z"] = 4, ["meta"] = { ["inventory"] = {  }, ["fields"] = {  } }, ["param2"] = 1, ["param1"] = 173 }, { ["y"] = 13, ["x"] = 3, ["name"] = "cottages:roof_connector_straw", ["z"] = 5, ["meta"] = { ["inventory"] = {  }, ["fields"] = {  } }, ["param2"] = 1, ["param1"] = 189 }, { ["y"] = 13, ["x"] = 3, ["name"] = "cottages:roof_connector_straw", ["z"] = 6, ["meta"] = { ["inventory"] = {  }, ["fields"] = {  } }, ["param2"] = 1, ["param1"] = 173 }, { ["y"] = 13, ["x"] = 3, ["name"] = "cottages:roof_connector_straw", ["z"] = 7, ["meta"] = { ["inventory"] = {  }, ["fields"] = {  } }, ["param2"] = 1, ["param1"] = 173 }, { ["y"] = 13, ["x"] = 3, ["name"] = "cottages:roof_connector_straw", ["z"] = 8, ["meta"] = { ["inventory"] = {  }, ["fields"] = {  } }, ["param2"] = 1, ["param1"] = 189 }, { ["y"] = 13, ["x"] = 3, ["name"] = "cottages:roof_flat_straw", ["z"] = 9, ["meta"] = { ["inventory"] = {  }, ["fields"] = {  } }, ["param2"] = 1, ["param1"] = 173 }, { ["y"] = 14, ["x"] = 3, ["name"] = "cottages:roof_connector_straw", ["z"] = 5, ["meta"] = { ["inventory"] = {  }, ["fields"] = {  } }, ["param2"] = 1, ["param1"] = 205 }, { ["y"] = 14, ["x"] = 3, ["name"] = "cottages:roof_connector_straw", ["z"] = 6, ["meta"] = { ["inventory"] = {  }, ["fields"] = {  } }, ["param2"] = 1, ["param1"] = 189 }, { ["y"] = 14, ["x"] = 3, ["name"] = "cottages:roof_connector_straw", ["z"] = 7, ["meta"] = { ["inventory"] = {  }, ["fields"] = {  } }, ["param2"] = 1, ["param1"] = 189 }, { ["y"] = 14, ["x"] = 3, ["name"] = "cottages:roof_connector_straw", ["z"] = 8, ["meta"] = { ["inventory"] = {  }, ["fields"] = {  } }, ["param2"] = 1, ["param1"] = 205 }, { ["y"] = 0, ["x"] = 4, ["name"] = "stairs:slab_cobble", ["z"] = 0, ["meta"] = { ["inventory"] = {  }, ["fields"] = {  } }, ["param2"] = 0, ["param1"] = 141 }, { ["y"] = 0, ["x"] = 4, ["name"] = "stairs:slab_cobble", ["z"] = 1, ["meta"] = { ["inventory"] = {  }, ["fields"] = {  } }, ["param2"] = 0, ["param1"] = 157 }, { ["y"] = 0, ["x"] = 4, ["name"] = "stairs:slab_cobble", ["z"] = 2, ["meta"] = { ["inventory"] = {  }, ["fields"] = {  } }, ["param2"] = 0, ["param1"] = 173 }, { ["y"] = 0, ["x"] = 4, ["name"] = "stairs:slab_cobble", ["z"] = 3, ["meta"] = { ["inventory"] = {  }, ["fields"] = {  } }, ["param2"] = 0, ["param1"] = 188 }, { ["y"] = 0, ["x"] = 4, ["name"] = "default:cobble", ["z"] = 4, ["meta"] = { ["inventory"] = {  }, ["fields"] = {  } }, ["param2"] = 0, ["param1"] = 0 }, { ["y"] = 0, ["x"] = 4, ["name"] = "default:cobble", ["z"] = 5, ["meta"] = { ["inventory"] = {  }, ["fields"] = {  } }, ["param2"] = 0, ["param1"] = 0 }, { ["y"] = 0, ["x"] = 4, ["name"] = "default:cobble", ["z"] = 6, ["meta"] = { ["inventory"] = {  }, ["fields"] = {  } }, ["param2"] = 0, ["param1"] = 0 }, { ["y"] = 0, ["x"] = 4, ["name"] = "default:cobble", ["z"] = 7, ["meta"] = { ["inventory"] = {  }, ["fields"] = {  } }, ["param2"] = 0, ["param1"] = 0 }, { ["y"] = 0, ["x"] = 4, ["name"] = "stairs:slab_cobble", ["z"] = 8, ["meta"] = { ["inventory"] = {  }, ["fields"] = {  } }, ["param2"] = 0, ["param1"] = 136 }, { ["y"] = 0, ["x"] = 4, ["name"] = "default:cobble", ["z"] = 9, ["meta"] = { ["inventory"] = {  }, ["fields"] = {  } }, ["param2"] = 0, ["param1"] = 0 }, { ["y"] = 0, ["x"] = 4, ["name"] = "default:cobble", ["z"] = 10, ["meta"] = { ["inventory"] = {  }, ["fields"] = {  } }, ["param2"] = 0, ["param1"] = 0 }, { ["y"] = 0, ["x"] = 4, ["name"] = "default:cobble", ["z"] = 11, ["meta"] = { ["inventory"] = {  }, ["fields"] = {  } }, ["param2"] = 0, ["param1"] = 0 }, { ["y"] = 0, ["x"] = 4, ["name"] = "default:cobble", ["z"] = 12, ["meta"] = { ["inventory"] = {  }, ["fields"] = {  } }, ["param2"] = 0, ["param1"] = 0 }, { ["y"] = 0, ["x"] = 4, ["name"] = "default:cobble", ["z"] = 13, ["meta"] = { ["inventory"] = {  }, ["fields"] = {  } }, ["param2"] = 0, ["param1"] = 0 }, { ["y"] = 0, ["x"] = 4, ["name"] = "default:cobble", ["z"] = 14, ["meta"] = { ["inventory"] = {  }, ["fields"] = {  } }, ["param2"] = 0, ["param1"] = 0 }, { ["y"] = 0, ["x"] = 4, ["name"] = "default:cobble", ["z"] = 15, ["meta"] = { ["inventory"] = {  }, ["fields"] = {  } }, ["param2"] = 0, ["param1"] = 0 }, { ["y"] = 0, ["x"] = 4, ["name"] = "default:cobble", ["z"] = 16, ["meta"] = { ["inventory"] = {  }, ["fields"] = {  } }, ["param2"] = 0, ["param1"] = 0 }, { ["y"] = 0, ["x"] = 4, ["name"] = "default:cobble", ["z"] = 17, ["meta"] = { ["inventory"] = {  }, ["fields"] = {  } }, ["param2"] = 0, ["param1"] = 0 }, { ["y"] = 0, ["x"] = 4, ["name"] = "default:cobble", ["z"] = 18, ["meta"] = { ["inventory"] = {  }, ["fields"] = {  } }, ["param2"] = 0, ["param1"] = 0 }, { ["y"] = 0, ["x"] = 4, ["name"] = "default:cobble", ["z"] = 19, ["meta"] = { ["inventory"] = {  }, ["fields"] = {  } }, ["param2"] = 0, ["param1"] = 0 }, { ["y"] = 0, ["x"] = 4, ["name"] = "stairs:slab_cobble", ["z"] = 20, ["meta"] = { ["inventory"] = {  }, ["fields"] = {  } }, ["param2"] = 0, ["param1"] = 136 }, { ["y"] = 0, ["x"] = 4, ["name"] = "stairs:slab_cobble", ["z"] = 21, ["meta"] = { ["inventory"] = {  }, ["fields"] = {  } }, ["param2"] = 0, ["param1"] = 153 }, { ["y"] = 0, ["x"] = 4, ["name"] = "stairs:slab_cobble", ["z"] = 22, ["meta"] = { ["inventory"] = {  }, ["fields"] = {  } }, ["param2"] = 0, ["param1"] = 170 }, { ["y"] = 0, ["x"] = 4, ["name"] = "default:cobble", ["z"] = 23, ["meta"] = { ["inventory"] = {  }, ["fields"] = {  } }, ["param2"] = 0, ["param1"] = 0 }, { ["y"] = 0, ["x"] = 4, ["name"] = "default:cobble", ["z"] = 24, ["meta"] = { ["inventory"] = {  }, ["fields"] = {  } }, ["param2"] = 0, ["param1"] = 0 }, { ["y"] = 0, ["x"] = 4, ["name"] = "default:cobble", ["z"] = 25, ["meta"] = { ["inventory"] = {  }, ["fields"] = {  } }, ["param2"] = 0, ["param1"] = 0 }, { ["y"] = 1, ["x"] = 4, ["name"] = "cottages:loam", ["z"] = 4, ["meta"] = { ["inventory"] = {  }, ["fields"] = {  } }, ["param2"] = 0, ["param1"] = 0 }, { ["y"] = 1, ["x"] = 4, ["name"] = "stairs:stair_wood", ["z"] = 6, ["meta"] = { ["inventory"] = {  }, ["fields"] = {  } }, ["param2"] = 0, ["param1"] = 187 }, { ["y"] = 1, ["x"] = 4, ["name"] = "cottages:chest_private", ["z"] = 7, ["meta"] = { ["inventory"] = {  }, ["fields"] = {  } }, ["param2"] = 3, ["param1"] = 0 }, { ["y"] = 1, ["x"] = 4, ["name"] = "cottages:loam", ["z"] = 9, ["meta"] = { ["inventory"] = {  }, ["fields"] = {  } }, ["param2"] = 0, ["param1"] = 0 }, { ["y"] = 1, ["x"] = 4, ["name"] = "cottages:bench", ["z"] = 10, ["meta"] = { ["inventory"] = {  }, ["fields"] = {  } }, ["param2"] = 2, ["param1"] = 204 }, { ["y"] = 1, ["x"] = 4, ["name"] = "default:fence_wood", ["z"] = 11, ["meta"] = { ["inventory"] = {  }, ["fields"] = {  } }, ["param2"] = 0, ["param1"] = 187 }, { ["y"] = 1, ["x"] = 4, ["name"] = "cottages:bench", ["z"] = 12, ["meta"] = { ["inventory"] = {  }, ["fields"] = {  } }, ["param2"] = 2, ["param1"] = 170 }, { ["y"] = 1, ["x"] = 4, ["name"] = "default:fence_wood", ["z"] = 13, ["meta"] = { ["inventory"] = {  }, ["fields"] = {  } }, ["param2"] = 0, ["param1"] = 170 }, { ["y"] = 1, ["x"] = 4, ["name"] = "cottages:bench", ["z"] = 14, ["meta"] = { ["inventory"] = {  }, ["fields"] = {  } }, ["param2"] = 2, ["param1"] = 153 }, { ["y"] = 1, ["x"] = 4, ["name"] = "default:fence_wood", ["z"] = 15, ["meta"] = { ["inventory"] = {  }, ["fields"] = {  } }, ["param2"] = 0, ["param1"] = 170 }, { ["y"] = 1, ["x"] = 4, ["name"] = "cottages:bench", ["z"] = 16, ["meta"] = { ["inventory"] = {  }, ["fields"] = {  } }, ["param2"] = 2, ["param1"] = 153 }, { ["y"] = 1, ["x"] = 4, ["name"] = "default:fence_wood", ["z"] = 17, ["meta"] = { ["inventory"] = {  }, ["fields"] = {  } }, ["param2"] = 0, ["param1"] = 170 }, { ["y"] = 1, ["x"] = 4, ["name"] = "cottages:bench", ["z"] = 18, ["meta"] = { ["inventory"] = {  }, ["fields"] = {  } }, ["param2"] = 2, ["param1"] = 153 }, { ["y"] = 1, ["x"] = 4, ["name"] = "default:fence_wood", ["z"] = 19, ["meta"] = { ["inventory"] = {  }, ["fields"] = {  } }, ["param2"] = 0, ["param1"] = 170 }, { ["y"] = 1, ["x"] = 4, ["name"] = "cottages:loam", ["z"] = 25, ["meta"] = { ["inventory"] = {  }, ["fields"] = {  } }, ["param2"] = 0, ["param1"] = 0 }, { ["y"] = 2, ["x"] = 4, ["name"] = "default:torch", ["z"] = 3, ["meta"] = { ["inventory"] = {  }, ["fields"] = {  } }, ["param2"] = 4, ["param1"] = 0 }, { ["y"] = 2, ["x"] = 4, ["name"] = "default:clay", ["z"] = 4, ["meta"] = { ["inventory"] = {  }, ["fields"] = {  } }, ["param2"] = 0, ["param1"] = 0 }, { ["y"] = 2, ["x"] = 4, ["name"] = "default:torch", ["z"] = 5, ["meta"] = { ["inventory"] = {  }, ["fields"] = {  } }, ["param2"] = 5, ["param1"] = 0 }, { ["y"] = 2, ["x"] = 4, ["name"] = "stairs:stair_wood", ["z"] = 7, ["meta"] = { ["inventory"] = {  }, ["fields"] = {  } }, ["param2"] = 0, ["param1"] = 187 }, { ["y"] = 2, ["x"] = 4, ["name"] = "default:clay", ["z"] = 9, ["meta"] = { ["inventory"] = {  }, ["fields"] = {  } }, ["param2"] = 0, ["param1"] = 0 }, { ["y"] = 2, ["x"] = 4, ["name"] = "default:torch", ["z"] = 10, ["meta"] = { ["inventory"] = {  }, ["fields"] = {  } }, ["param2"] = 5, ["param1"] = 0 }, { ["y"] = 2, ["x"] = 4, ["name"] = "default:torch", ["z"] = 24, ["meta"] = { ["inventory"] = {  }, ["fields"] = {  } }, ["param2"] = 4, ["param1"] = 0 }, { ["y"] = 2, ["x"] = 4, ["name"] = "cottages:loam", ["z"] = 25, ["meta"] = { ["inventory"] = {  }, ["fields"] = {  } }, ["param2"] = 0, ["param1"] = 0 }, { ["y"] = 3, ["x"] = 4, ["name"] = "cottages:loam", ["z"] = 4, ["meta"] = { ["inventory"] = {  }, ["fields"] = {  } }, ["param2"] = 0, ["param1"] = 0 }, { ["y"] = 3, ["x"] = 4, ["name"] = "stairs:slab_wood", ["z"] = 8, ["meta"] = { ["inventory"] = {  }, ["fields"] = {  } }, ["param2"] = 0, ["param1"] = 187 }, { ["y"] = 3, ["x"] = 4, ["name"] = "cottages:loam", ["z"] = 9, ["meta"] = { ["inventory"] = {  }, ["fields"] = {  } }, ["param2"] = 0, ["param1"] = 0 }, { ["y"] = 3, ["x"] = 4, ["name"] = "cottages:loam", ["z"] = 25, ["meta"] = { ["inventory"] = {  }, ["fields"] = {  } }, ["param2"] = 0, ["param1"] = 0 }, { ["y"] = 4, ["x"] = 4, ["name"] = "default:clay", ["z"] = 4, ["meta"] = { ["inventory"] = {  }, ["fields"] = {  } }, ["param2"] = 0, ["param1"] = 0 }, { ["y"] = 4, ["x"] = 4, ["name"] = "default:torch", ["z"] = 5, ["meta"] = { ["inventory"] = {  }, ["fields"] = {  } }, ["param2"] = 3, ["param1"] = 0 }, { ["y"] = 4, ["x"] = 4, ["name"] = "default:torch", ["z"] = 7, ["meta"] = { ["inventory"] = {  }, ["fields"] = {  } }, ["param2"] = 3, ["param1"] = 0 }, { ["y"] = 4, ["x"] = 4, ["name"] = "default:clay", ["z"] = 9, ["meta"] = { ["inventory"] = {  }, ["fields"] = {  } }, ["param2"] = 0, ["param1"] = 0 }, { ["y"] = 4, ["x"] = 4, ["name"] = "cottages:loam", ["z"] = 25, ["meta"] = { ["inventory"] = {  }, ["fields"] = {  } }, ["param2"] = 0, ["param1"] = 0 }, { ["y"] = 5, ["x"] = 4, ["name"] = "cottages:loam", ["z"] = 4, ["meta"] = { ["inventory"] = {  }, ["fields"] = {  } }, ["param2"] = 0, ["param1"] = 0 }, { ["y"] = 5, ["x"] = 4, ["name"] = "default:torch", ["z"] = 5, ["meta"] = { ["inventory"] = {  }, ["fields"] = {  } }, ["param2"] = 5, ["param1"] = 0 }, { ["y"] = 5, ["x"] = 4, ["name"] = "default:torch", ["z"] = 8, ["meta"] = { ["inventory"] = {  }, ["fields"] = {  } }, ["param2"] = 4, ["param1"] = 0 }, { ["y"] = 5, ["x"] = 4, ["name"] = "cottages:loam", ["z"] = 9, ["meta"] = { ["inventory"] = {  }, ["fields"] = {  } }, ["param2"] = 0, ["param1"] = 0 }, { ["y"] = 5, ["x"] = 4, ["name"] = "default:torch", ["z"] = 10, ["meta"] = { ["inventory"] = {  }, ["fields"] = {  } }, ["param2"] = 5, ["param1"] = 0 }, { ["y"] = 5, ["x"] = 4, ["name"] = "default:torch", ["z"] = 23, ["meta"] = { ["inventory"] = {  }, ["fields"] = {  } }, ["param2"] = 4, ["param1"] = 0 }, { ["y"] = 5, ["x"] = 4, ["name"] = "cottages:loam", ["z"] = 24, ["meta"] = { ["inventory"] = {  }, ["fields"] = {  } }, ["param2"] = 0, ["param1"] = 0 }, { ["y"] = 5, ["x"] = 4, ["name"] = "cottages:roof_connector_straw", ["z"] = 25, ["meta"] = { ["inventory"] = {  }, ["fields"] = {  } }, ["param2"] = 2, ["param1"] = 125 }, { ["y"] = 6, ["x"] = 4, ["name"] = "default:clay", ["z"] = 4, ["meta"] = { ["inventory"] = {  }, ["fields"] = {  } }, ["param2"] = 0, ["param1"] = 0 }, { ["y"] = 6, ["x"] = 4, ["name"] = "default:clay", ["z"] = 9, ["meta"] = { ["inventory"] = {  }, ["fields"] = {  } }, ["param2"] = 0, ["param1"] = 0 }, { ["y"] = 6, ["x"] = 4, ["name"] = "cottages:loam", ["z"] = 23, ["meta"] = { ["inventory"] = {  }, ["fields"] = {  } }, ["param2"] = 0, ["param1"] = 0 }, { ["y"] = 6, ["x"] = 4, ["name"] = "cottages:roof_connector_straw", ["z"] = 24, ["meta"] = { ["inventory"] = {  }, ["fields"] = {  } }, ["param2"] = 2, ["param1"] = 141 }, { ["y"] = 7, ["x"] = 4, ["name"] = "cottages:loam", ["z"] = 4, ["meta"] = { ["inventory"] = {  }, ["fields"] = {  } }, ["param2"] = 0, ["param1"] = 0 }, { ["y"] = 7, ["x"] = 4, ["name"] = "stairs:slab_wood", ["z"] = 5, ["meta"] = { ["inventory"] = {  }, ["fields"] = {  } }, ["param2"] = 0, ["param1"] = 187 }, { ["y"] = 7, ["x"] = 4, ["name"] = "stairs:stair_wood", ["z"] = 6, ["meta"] = { ["inventory"] = {  }, ["fields"] = {  } }, ["param2"] = 0, ["param1"] = 187 }, { ["y"] = 7, ["x"] = 4, ["name"] = "default:torch", ["z"] = 8, ["meta"] = { ["inventory"] = {  }, ["fields"] = {  } }, ["param2"] = 3, ["param1"] = 0 }, { ["y"] = 7, ["x"] = 4, ["name"] = "cottages:loam", ["z"] = 9, ["meta"] = { ["inventory"] = {  }, ["fields"] = {  } }, ["param2"] = 0, ["param1"] = 0 }, { ["y"] = 7, ["x"] = 4, ["name"] = "cottages:loam", ["z"] = 23, ["meta"] = { ["inventory"] = {  }, ["fields"] = {  } }, ["param2"] = 0, ["param1"] = 0 }, { ["y"] = 8, ["x"] = 4, ["name"] = "default:clay", ["z"] = 4, ["meta"] = { ["inventory"] = {  }, ["fields"] = {  } }, ["param2"] = 0, ["param1"] = 0 }, { ["y"] = 8, ["x"] = 4, ["name"] = "stairs:stair_wood", ["z"] = 7, ["meta"] = { ["inventory"] = {  }, ["fields"] = {  } }, ["param2"] = 0, ["param1"] = 187 }, { ["y"] = 8, ["x"] = 4, ["name"] = "default:clay", ["z"] = 9, ["meta"] = { ["inventory"] = {  }, ["fields"] = {  } }, ["param2"] = 0, ["param1"] = 0 }, { ["y"] = 8, ["x"] = 4, ["name"] = "cottages:roof_straw", ["z"] = 10, ["meta"] = { ["inventory"] = {  }, ["fields"] = {  } }, ["param2"] = 1, ["param1"] = 188 }, { ["y"] = 8, ["x"] = 4, ["name"] = "cottages:roof_straw", ["z"] = 11, ["meta"] = { ["inventory"] = {  }, ["fields"] = {  } }, ["param2"] = 1, ["param1"] = 189 }, { ["y"] = 8, ["x"] = 4, ["name"] = "cottages:roof_straw", ["z"] = 12, ["meta"] = { ["inventory"] = {  }, ["fields"] = {  } }, ["param2"] = 1, ["param1"] = 205 }, { ["y"] = 8, ["x"] = 4, ["name"] = "cottages:roof_straw", ["z"] = 13, ["meta"] = { ["inventory"] = {  }, ["fields"] = {  } }, ["param2"] = 1, ["param1"] = 189 }, { ["y"] = 8, ["x"] = 4, ["name"] = "cottages:roof_straw", ["z"] = 14, ["meta"] = { ["inventory"] = {  }, ["fields"] = {  } }, ["param2"] = 1, ["param1"] = 189 }, { ["y"] = 8, ["x"] = 4, ["name"] = "cottages:roof_straw", ["z"] = 15, ["meta"] = { ["inventory"] = {  }, ["fields"] = {  } }, ["param2"] = 1, ["param1"] = 189 }, { ["y"] = 8, ["x"] = 4, ["name"] = "cottages:roof_straw", ["z"] = 16, ["meta"] = { ["inventory"] = {  }, ["fields"] = {  } }, ["param2"] = 1, ["param1"] = 205 }, { ["y"] = 8, ["x"] = 4, ["name"] = "cottages:roof_straw", ["z"] = 17, ["meta"] = { ["inventory"] = {  }, ["fields"] = {  } }, ["param2"] = 1, ["param1"] = 189 }, { ["y"] = 8, ["x"] = 4, ["name"] = "cottages:roof_straw", ["z"] = 18, ["meta"] = { ["inventory"] = {  }, ["fields"] = {  } }, ["param2"] = 1, ["param1"] = 173 }, { ["y"] = 8, ["x"] = 4, ["name"] = "cottages:roof_straw", ["z"] = 19, ["meta"] = { ["inventory"] = {  }, ["fields"] = {  } }, ["param2"] = 1, ["param1"] = 189 }, { ["y"] = 8, ["x"] = 4, ["name"] = "cottages:roof_straw", ["z"] = 20, ["meta"] = { ["inventory"] = {  }, ["fields"] = {  } }, ["param2"] = 1, ["param1"] = 205 }, { ["y"] = 8, ["x"] = 4, ["name"] = "cottages:roof_straw", ["z"] = 21, ["meta"] = { ["inventory"] = {  }, ["fields"] = {  } }, ["param2"] = 1, ["param1"] = 189 }, { ["y"] = 8, ["x"] = 4, ["name"] = "cottages:roof_straw", ["z"] = 22, ["meta"] = { ["inventory"] = {  }, ["fields"] = {  } }, ["param2"] = 1, ["param1"] = 205 }, { ["y"] = 8, ["x"] = 4, ["name"] = "cottages:roof_connector_straw", ["z"] = 23, ["meta"] = { ["inventory"] = {  }, ["fields"] = {  } }, ["param2"] = 1, ["param1"] = 189 }, { ["y"] = 9, ["x"] = 4, ["name"] = "cottages:loam", ["z"] = 4, ["meta"] = { ["inventory"] = {  }, ["fields"] = {  } }, ["param2"] = 0, ["param1"] = 0 }, { ["y"] = 9, ["x"] = 4, ["name"] = "default:ladder", ["z"] = 7, ["meta"] = { ["inventory"] = {  }, ["fields"] = {  } }, ["param2"] = 3, ["param1"] = 187 }, { ["y"] = 9, ["x"] = 4, ["name"] = "stairs:slab_wood", ["z"] = 8, ["meta"] = { ["inventory"] = {  }, ["fields"] = {  } }, ["param2"] = 0, ["param1"] = 204 }, { ["y"] = 9, ["x"] = 4, ["name"] = "cottages:loam", ["z"] = 9, ["meta"] = { ["inventory"] = {  }, ["fields"] = {  } }, ["param2"] = 0, ["param1"] = 0 }, { ["y"] = 10, ["x"] = 4, ["name"] = "default:clay", ["z"] = 4, ["meta"] = { ["inventory"] = {  }, ["fields"] = {  } }, ["param2"] = 0, ["param1"] = 0 }, { ["y"] = 10, ["x"] = 4, ["name"] = "default:torch", ["z"] = 5, ["meta"] = { ["inventory"] = {  }, ["fields"] = {  } }, ["param2"] = 3, ["param1"] = 0 }, { ["y"] = 10, ["x"] = 4, ["name"] = "default:ladder", ["z"] = 7, ["meta"] = { ["inventory"] = {  }, ["fields"] = {  } }, ["param2"] = 3, ["param1"] = 204 }, { ["y"] = 10, ["x"] = 4, ["name"] = "default:torch", ["z"] = 8, ["meta"] = { ["inventory"] = {  }, ["fields"] = {  } }, ["param2"] = 3, ["param1"] = 0 }, { ["y"] = 10, ["x"] = 4, ["name"] = "default:clay", ["z"] = 9, ["meta"] = { ["inventory"] = {  }, ["fields"] = {  } }, ["param2"] = 0, ["param1"] = 0 }, { ["y"] = 11, ["x"] = 4, ["name"] = "cottages:loam", ["z"] = 4, ["meta"] = { ["inventory"] = {  }, ["fields"] = {  } }, ["param2"] = 0, ["param1"] = 0 }, { ["y"] = 11, ["x"] = 4, ["name"] = "stairs:slab_wood", ["z"] = 5, ["meta"] = { ["inventory"] = {  }, ["fields"] = {  } }, ["param2"] = 0, ["param1"] = 204 }, { ["y"] = 11, ["x"] = 4, ["name"] = "stairs:slab_wood", ["z"] = 6, ["meta"] = { ["inventory"] = {  }, ["fields"] = {  } }, ["param2"] = 0, ["param1"] = 187 }, { ["y"] = 11, ["x"] = 4, ["name"] = "default:ladder", ["z"] = 7, ["meta"] = { ["inventory"] = {  }, ["fields"] = {  } }, ["param2"] = 3, ["param1"] = 187 }, { ["y"] = 11, ["x"] = 4, ["name"] = "cottages:loam", ["z"] = 9, ["meta"] = { ["inventory"] = {  }, ["fields"] = {  } }, ["param2"] = 0, ["param1"] = 0 }, { ["y"] = 12, ["x"] = 4, ["name"] = "cottages:roof_straw", ["z"] = 3, ["meta"] = { ["inventory"] = {  }, ["fields"] = {  } }, ["param2"] = 0, ["param1"] = 157 }, { ["y"] = 12, ["x"] = 4, ["name"] = "default:clay", ["z"] = 4, ["meta"] = { ["inventory"] = {  }, ["fields"] = {  } }, ["param2"] = 0, ["param1"] = 0 }, { ["y"] = 12, ["x"] = 4, ["name"] = "default:torch", ["z"] = 5, ["meta"] = { ["inventory"] = {  }, ["fields"] = {  } }, ["param2"] = 3, ["param1"] = 0 }, { ["y"] = 12, ["x"] = 4, ["name"] = "default:ladder", ["z"] = 7, ["meta"] = { ["inventory"] = {  }, ["fields"] = {  } }, ["param2"] = 3, ["param1"] = 204 }, { ["y"] = 12, ["x"] = 4, ["name"] = "default:torch", ["z"] = 8, ["meta"] = { ["inventory"] = {  }, ["fields"] = {  } }, ["param2"] = 3, ["param1"] = 0 }, { ["y"] = 12, ["x"] = 4, ["name"] = "default:clay", ["z"] = 9, ["meta"] = { ["inventory"] = {  }, ["fields"] = {  } }, ["param2"] = 0, ["param1"] = 0 }, { ["y"] = 12, ["x"] = 4, ["name"] = "cottages:roof_straw", ["z"] = 10, ["meta"] = { ["inventory"] = {  }, ["fields"] = {  } }, ["param2"] = 2, ["param1"] = 157 }, { ["y"] = 13, ["x"] = 4, ["name"] = "cottages:roof_connector_straw", ["z"] = 4, ["meta"] = { ["inventory"] = {  }, ["fields"] = {  } }, ["param2"] = 0, ["param1"] = 189 }, { ["y"] = 13, ["x"] = 4, ["name"] = "default:ladder", ["z"] = 7, ["meta"] = { ["inventory"] = {  }, ["fields"] = {  } }, ["param2"] = 3, ["param1"] = 188 }, { ["y"] = 13, ["x"] = 4, ["name"] = "cottages:roof_connector_straw", ["z"] = 9, ["meta"] = { ["inventory"] = {  }, ["fields"] = {  } }, ["param2"] = 2, ["param1"] = 189 }, { ["y"] = 14, ["x"] = 4, ["name"] = "cottages:roof_connector_straw", ["z"] = 4, ["meta"] = { ["inventory"] = {  }, ["fields"] = {  } }, ["param2"] = 0, ["param1"] = 205 }, { ["y"] = 14, ["x"] = 4, ["name"] = "default:torch", ["z"] = 5, ["meta"] = { ["inventory"] = {  }, ["fields"] = {  } }, ["param2"] = 3, ["param1"] = 0 }, { ["y"] = 14, ["x"] = 4, ["name"] = "default:ladder", ["z"] = 7, ["meta"] = { ["inventory"] = {  }, ["fields"] = {  } }, ["param2"] = 3, ["param1"] = 204 }, { ["y"] = 14, ["x"] = 4, ["name"] = "default:torch", ["z"] = 8, ["meta"] = { ["inventory"] = {  }, ["fields"] = {  } }, ["param2"] = 4, ["param1"] = 0 }, { ["y"] = 14, ["x"] = 4, ["name"] = "cottages:roof_connector_straw", ["z"] = 9, ["meta"] = { ["inventory"] = {  }, ["fields"] = {  } }, ["param2"] = 2, ["param1"] = 205 }, { ["y"] = 15, ["x"] = 4, ["name"] = "cottages:roof_flat_straw", ["z"] = 5, ["meta"] = { ["inventory"] = {  }, ["fields"] = {  } }, ["param2"] = 1, ["param1"] = 205 }, { ["y"] = 15, ["x"] = 4, ["name"] = "cottages:roof_connector_straw", ["z"] = 6, ["meta"] = { ["inventory"] = {  }, ["fields"] = {  } }, ["param2"] = 1, ["param1"] = 189 }, { ["y"] = 15, ["x"] = 4, ["name"] = "cottages:roof_connector_straw", ["z"] = 7, ["meta"] = { ["inventory"] = {  }, ["fields"] = {  } }, ["param2"] = 1, ["param1"] = 189 }, { ["y"] = 15, ["x"] = 4, ["name"] = "cottages:roof_flat_straw", ["z"] = 8, ["meta"] = { ["inventory"] = {  }, ["fields"] = {  } }, ["param2"] = 1, ["param1"] = 205 }, { ["y"] = 16, ["x"] = 4, ["name"] = "cottages:roof_connector_straw", ["z"] = 6, ["meta"] = { ["inventory"] = {  }, ["fields"] = {  } }, ["param2"] = 1, ["param1"] = 189 }, { ["y"] = 16, ["x"] = 4, ["name"] = "cottages:roof_connector_straw", ["z"] = 7, ["meta"] = { ["inventory"] = {  }, ["fields"] = {  } }, ["param2"] = 1, ["param1"] = 205 }, { ["y"] = 0, ["x"] = 5, ["name"] = "stairs:slab_cobble", ["z"] = 0, ["meta"] = { ["inventory"] = {  }, ["fields"] = {  } }, ["param2"] = 0, ["param1"] = 125 }, { ["y"] = 0, ["x"] = 5, ["name"] = "stairs:slab_cobble", ["z"] = 1, ["meta"] = { ["inventory"] = {  }, ["fields"] = {  } }, ["param2"] = 0, ["param1"] = 141 }, { ["y"] = 0, ["x"] = 5, ["name"] = "stairs:slab_cobble", ["z"] = 2, ["meta"] = { ["inventory"] = {  }, ["fields"] = {  } }, ["param2"] = 0, ["param1"] = 157 }, { ["y"] = 0, ["x"] = 5, ["name"] = "stairs:slab_cobble", ["z"] = 3, ["meta"] = { ["inventory"] = {  }, ["fields"] = {  } }, ["param2"] = 0, ["param1"] = 172 }, { ["y"] = 0, ["x"] = 5, ["name"] = "stairs:stair_cobble", ["z"] = 4, ["meta"] = { ["inventory"] = {  }, ["fields"] = {  } }, ["param2"] = 0, ["param1"] = 155 }, { ["y"] = 0, ["x"] = 5, ["name"] = "stairs:slab_cobble", ["z"] = 5, ["meta"] = { ["inventory"] = {  }, ["fields"] = {  } }, ["param2"] = 0, ["param1"] = 170 }, { ["y"] = 0, ["x"] = 5, ["name"] = "stairs:slab_cobble", ["z"] = 6, ["meta"] = { ["inventory"] = {  }, ["fields"] = {  } }, ["param2"] = 0, ["param1"] = 153 }, { ["y"] = 0, ["x"] = 5, ["name"] = "stairs:slab_cobble", ["z"] = 7, ["meta"] = { ["inventory"] = {  }, ["fields"] = {  } }, ["param2"] = 0, ["param1"] = 136 }, { ["y"] = 0, ["x"] = 5, ["name"] = "stairs:slab_cobble", ["z"] = 8, ["meta"] = { ["inventory"] = {  }, ["fields"] = {  } }, ["param2"] = 0, ["param1"] = 136 }, { ["y"] = 0, ["x"] = 5, ["name"] = "stairs:slab_cobble", ["z"] = 9, ["meta"] = { ["inventory"] = {  }, ["fields"] = {  } }, ["param2"] = 0, ["param1"] = 153 }, { ["y"] = 0, ["x"] = 5, ["name"] = "stairs:slab_cobble", ["z"] = 10, ["meta"] = { ["inventory"] = {  }, ["fields"] = {  } }, ["param2"] = 0, ["param1"] = 170 }, { ["y"] = 0, ["x"] = 5, ["name"] = "stairs:slab_cobble", ["z"] = 11, ["meta"] = { ["inventory"] = {  }, ["fields"] = {  } }, ["param2"] = 0, ["param1"] = 153 }, { ["y"] = 0, ["x"] = 5, ["name"] = "stairs:slab_cobble", ["z"] = 12, ["meta"] = { ["inventory"] = {  }, ["fields"] = {  } }, ["param2"] = 0, ["param1"] = 136 }, { ["y"] = 0, ["x"] = 5, ["name"] = "stairs:slab_cobble", ["z"] = 13, ["meta"] = { ["inventory"] = {  }, ["fields"] = {  } }, ["param2"] = 0, ["param1"] = 136 }, { ["y"] = 0, ["x"] = 5, ["name"] = "stairs:slab_cobble", ["z"] = 14, ["meta"] = { ["inventory"] = {  }, ["fields"] = {  } }, ["param2"] = 0, ["param1"] = 119 }, { ["y"] = 0, ["x"] = 5, ["name"] = "stairs:slab_cobble", ["z"] = 15, ["meta"] = { ["inventory"] = {  }, ["fields"] = {  } }, ["param2"] = 0, ["param1"] = 136 }, { ["y"] = 0, ["x"] = 5, ["name"] = "stairs:slab_cobble", ["z"] = 16, ["meta"] = { ["inventory"] = {  }, ["fields"] = {  } }, ["param2"] = 0, ["param1"] = 119 }, { ["y"] = 0, ["x"] = 5, ["name"] = "stairs:slab_cobble", ["z"] = 17, ["meta"] = { ["inventory"] = {  }, ["fields"] = {  } }, ["param2"] = 0, ["param1"] = 136 }, { ["y"] = 0, ["x"] = 5, ["name"] = "stairs:slab_cobble", ["z"] = 18, ["meta"] = { ["inventory"] = {  }, ["fields"] = {  } }, ["param2"] = 0, ["param1"] = 119 }, { ["y"] = 0, ["x"] = 5, ["name"] = "stairs:slab_cobble", ["z"] = 19, ["meta"] = { ["inventory"] = {  }, ["fields"] = {  } }, ["param2"] = 0, ["param1"] = 136 }, { ["y"] = 0, ["x"] = 5, ["name"] = "stairs:slab_cobble", ["z"] = 20, ["meta"] = { ["inventory"] = {  }, ["fields"] = {  } }, ["param2"] = 0, ["param1"] = 153 }, { ["y"] = 0, ["x"] = 5, ["name"] = "stairs:slab_cobble", ["z"] = 21, ["meta"] = { ["inventory"] = {  }, ["fields"] = {  } }, ["param2"] = 0, ["param1"] = 170 }, { ["y"] = 0, ["x"] = 5, ["name"] = "default:cobble", ["z"] = 22, ["meta"] = { ["inventory"] = {  }, ["fields"] = {  } }, ["param2"] = 0, ["param1"] = 0 }, { ["y"] = 0, ["x"] = 5, ["name"] = "default:cobble", ["z"] = 23, ["meta"] = { ["inventory"] = {  }, ["fields"] = {  } }, ["param2"] = 0, ["param1"] = 0 }, { ["y"] = 0, ["x"] = 5, ["name"] = "default:cobble", ["z"] = 24, ["meta"] = { ["inventory"] = {  }, ["fields"] = {  } }, ["param2"] = 0, ["param1"] = 0 }, { ["y"] = 0, ["x"] = 5, ["name"] = "default:cobble", ["z"] = 25, ["meta"] = { ["inventory"] = {  }, ["fields"] = {  } }, ["param2"] = 0, ["param1"] = 0 }, { ["y"] = 1, ["x"] = 5, ["name"] = "cottages:half_door", ["z"] = 4, ["meta"] = { ["inventory"] = {  }, ["fields"] = {  } }, ["param2"] = 0, ["param1"] = 172 }, { ["y"] = 1, ["x"] = 5, ["name"] = "default:cobble", ["z"] = 22, ["meta"] = { ["inventory"] = {  }, ["fields"] = {  } }, ["param2"] = 0, ["param1"] = 0 }, { ["y"] = 1, ["x"] = 5, ["name"] = "cottages:loam", ["z"] = 25, ["meta"] = { ["inventory"] = {  }, ["fields"] = {  } }, ["param2"] = 0, ["param1"] = 0 }, { ["y"] = 2, ["x"] = 5, ["name"] = "cottages:half_door", ["z"] = 4, ["meta"] = { ["inventory"] = {  }, ["fields"] = {  } }, ["param2"] = 0, ["param1"] = 188 }, { ["y"] = 2, ["x"] = 5, ["name"] = "default:torch", ["z"] = 22, ["meta"] = { ["inventory"] = {  }, ["fields"] = {  } }, ["param2"] = 1, ["param1"] = 0 }, { ["y"] = 2, ["x"] = 5, ["name"] = "cottages:glass_pane", ["z"] = 25, ["meta"] = { ["inventory"] = {  }, ["fields"] = {  } }, ["param2"] = 0, ["param1"] = 189 }, { ["y"] = 3, ["x"] = 5, ["name"] = "cottages:loam", ["z"] = 4, ["meta"] = { ["inventory"] = {  }, ["fields"] = {  } }, ["param2"] = 0, ["param1"] = 0 }, { ["y"] = 3, ["x"] = 5, ["name"] = "default:ladder", ["z"] = 6, ["meta"] = { ["inventory"] = {  }, ["fields"] = {  } }, ["param2"] = 4, ["param1"] = 170 }, { ["y"] = 3, ["x"] = 5, ["name"] = "stairs:stair_wood", ["z"] = 7, ["meta"] = { ["inventory"] = {  }, ["fields"] = {  } }, ["param2"] = 2, ["param1"] = 187 }, { ["y"] = 3, ["x"] = 5, ["name"] = "stairs:slab_wood", ["z"] = 8, ["meta"] = { ["inventory"] = {  }, ["fields"] = {  } }, ["param2"] = 0, ["param1"] = 170 }, { ["y"] = 3, ["x"] = 5, ["name"] = "cottages:loam", ["z"] = 9, ["meta"] = { ["inventory"] = {  }, ["fields"] = {  } }, ["param2"] = 0, ["param1"] = 0 }, { ["y"] = 3, ["x"] = 5, ["name"] = "cottages:glass_pane", ["z"] = 25, ["meta"] = { ["inventory"] = {  }, ["fields"] = {  } }, ["param2"] = 0, ["param1"] = 173 }, { ["y"] = 4, ["x"] = 5, ["name"] = "cottages:glass_pane", ["z"] = 4, ["meta"] = { ["inventory"] = {  }, ["fields"] = {  } }, ["param2"] = 2, ["param1"] = 188 }, { ["y"] = 4, ["x"] = 5, ["name"] = "default:ladder", ["z"] = 6, ["meta"] = { ["inventory"] = {  }, ["fields"] = {  } }, ["param2"] = 4, ["param1"] = 187 }, { ["y"] = 4, ["x"] = 5, ["name"] = "cottages:bench", ["z"] = 7, ["meta"] = { ["inventory"] = {  }, ["fields"] = {  } }, ["param2"] = 2, ["param1"] = 204 }, { ["y"] = 4, ["x"] = 5, ["name"] = "default:fence_wood", ["z"] = 9, ["meta"] = { ["inventory"] = {  }, ["fields"] = {  } }, ["param2"] = 0, ["param1"] = 170 }, { ["y"] = 4, ["x"] = 5, ["name"] = "cottages:glass_pane", ["z"] = 25, ["meta"] = { ["inventory"] = {  }, ["fields"] = {  } }, ["param2"] = 0, ["param1"] = 157 }, { ["y"] = 5, ["x"] = 5, ["name"] = "cottages:glass_pane", ["z"] = 4, ["meta"] = { ["inventory"] = {  }, ["fields"] = {  } }, ["param2"] = 2, ["param1"] = 188 }, { ["y"] = 5, ["x"] = 5, ["name"] = "default:ladder", ["z"] = 7, ["meta"] = { ["inventory"] = {  }, ["fields"] = {  } }, ["param2"] = 5, ["param1"] = 187 }, { ["y"] = 5, ["x"] = 5, ["name"] = "cottages:loam", ["z"] = 24, ["meta"] = { ["inventory"] = {  }, ["fields"] = {  } }, ["param2"] = 0, ["param1"] = 0 }, { ["y"] = 5, ["x"] = 5, ["name"] = "cottages:roof_connector_straw", ["z"] = 25, ["meta"] = { ["inventory"] = {  }, ["fields"] = {  } }, ["param2"] = 2, ["param1"] = 141 }, { ["y"] = 6, ["x"] = 5, ["name"] = "cottages:loam", ["z"] = 4, ["meta"] = { ["inventory"] = {  }, ["fields"] = {  } }, ["param2"] = 0, ["param1"] = 0 }, { ["y"] = 6, ["x"] = 5, ["name"] = "stairs:stair_wood", ["z"] = 5, ["meta"] = { ["inventory"] = {  }, ["fields"] = {  } }, ["param2"] = 3, ["param1"] = 187 }, { ["y"] = 6, ["x"] = 5, ["name"] = "default:ladder", ["z"] = 6, ["meta"] = { ["inventory"] = {  }, ["fields"] = {  } }, ["param2"] = 1, ["param1"] = 170 }, { ["y"] = 6, ["x"] = 5, ["name"] = "cottages:loam", ["z"] = 9, ["meta"] = { ["inventory"] = {  }, ["fields"] = {  } }, ["param2"] = 0, ["param1"] = 0 }, { ["y"] = 6, ["x"] = 5, ["name"] = "cottages:loam", ["z"] = 23, ["meta"] = { ["inventory"] = {  }, ["fields"] = {  } }, ["param2"] = 0, ["param1"] = 0 }, { ["y"] = 6, ["x"] = 5, ["name"] = "cottages:roof_straw", ["z"] = 24, ["meta"] = { ["inventory"] = {  }, ["fields"] = {  } }, ["param2"] = 2, ["param1"] = 125 }, { ["y"] = 7, ["x"] = 5, ["name"] = "cottages:loam", ["z"] = 4, ["meta"] = { ["inventory"] = {  }, ["fields"] = {  } }, ["param2"] = 0, ["param1"] = 0 }, { ["y"] = 7, ["x"] = 5, ["name"] = "cottages:loam", ["z"] = 9, ["meta"] = { ["inventory"] = {  }, ["fields"] = {  } }, ["param2"] = 0, ["param1"] = 0 }, { ["y"] = 7, ["x"] = 5, ["name"] = "cottages:loam", ["z"] = 23, ["meta"] = { ["inventory"] = {  }, ["fields"] = {  } }, ["param2"] = 0, ["param1"] = 0 }, { ["y"] = 8, ["x"] = 5, ["name"] = "cottages:loam", ["z"] = 4, ["meta"] = { ["inventory"] = {  }, ["fields"] = {  } }, ["param2"] = 0, ["param1"] = 0 }, { ["y"] = 8, ["x"] = 5, ["name"] = "default:torch", ["z"] = 5, ["meta"] = { ["inventory"] = {  }, ["fields"] = {  } }, ["param2"] = 5, ["param1"] = 0 }, { ["y"] = 8, ["x"] = 5, ["name"] = "cottages:loam", ["z"] = 9, ["meta"] = { ["inventory"] = {  }, ["fields"] = {  } }, ["param2"] = 0, ["param1"] = 0 }, { ["y"] = 8, ["x"] = 5, ["name"] = "default:torch", ["z"] = 12, ["meta"] = { ["inventory"] = {  }, ["fields"] = {  } }, ["param2"] = 3, ["param1"] = 0 }, { ["y"] = 8, ["x"] = 5, ["name"] = "default:torch", ["z"] = 16, ["meta"] = { ["inventory"] = {  }, ["fields"] = {  } }, ["param2"] = 3, ["param1"] = 0 }, { ["y"] = 8, ["x"] = 5, ["name"] = "default:torch", ["z"] = 20, ["meta"] = { ["inventory"] = {  }, ["fields"] = {  } }, ["param2"] = 3, ["param1"] = 0 }, { ["y"] = 8, ["x"] = 5, ["name"] = "default:torch", ["z"] = 22, ["meta"] = { ["inventory"] = {  }, ["fields"] = {  } }, ["param2"] = 4, ["param1"] = 0 }, { ["y"] = 8, ["x"] = 5, ["name"] = "cottages:loam", ["z"] = 23, ["meta"] = { ["inventory"] = {  }, ["fields"] = {  } }, ["param2"] = 0, ["param1"] = 0 }, { ["y"] = 9, ["x"] = 5, ["name"] = "cottages:loam", ["z"] = 4, ["meta"] = { ["inventory"] = {  }, ["fields"] = {  } }, ["param2"] = 0, ["param1"] = 0 }, { ["y"] = 9, ["x"] = 5, ["name"] = "stairs:stair_wood", ["z"] = 8, ["meta"] = { ["inventory"] = {  }, ["fields"] = {  } }, ["param2"] = 1, ["param1"] = 187 }, { ["y"] = 9, ["x"] = 5, ["name"] = "cottages:loam", ["z"] = 9, ["meta"] = { ["inventory"] = {  }, ["fields"] = {  } }, ["param2"] = 0, ["param1"] = 0 }, { ["y"] = 9, ["x"] = 5, ["name"] = "cottages:roof_straw", ["z"] = 10, ["meta"] = { ["inventory"] = {  }, ["fields"] = {  } }, ["param2"] = 1, ["param1"] = 188 }, { ["y"] = 9, ["x"] = 5, ["name"] = "cottages:roof_straw", ["z"] = 11, ["meta"] = { ["inventory"] = {  }, ["fields"] = {  } }, ["param2"] = 1, ["param1"] = 189 }, { ["y"] = 9, ["x"] = 5, ["name"] = "cottages:roof_straw", ["z"] = 12, ["meta"] = { ["inventory"] = {  }, ["fields"] = {  } }, ["param2"] = 1, ["param1"] = 205 }, { ["y"] = 9, ["x"] = 5, ["name"] = "cottages:roof_straw", ["z"] = 13, ["meta"] = { ["inventory"] = {  }, ["fields"] = {  } }, ["param2"] = 1, ["param1"] = 189 }, { ["y"] = 9, ["x"] = 5, ["name"] = "cottages:roof_straw", ["z"] = 14, ["meta"] = { ["inventory"] = {  }, ["fields"] = {  } }, ["param2"] = 1, ["param1"] = 189 }, { ["y"] = 9, ["x"] = 5, ["name"] = "cottages:roof_straw", ["z"] = 15, ["meta"] = { ["inventory"] = {  }, ["fields"] = {  } }, ["param2"] = 1, ["param1"] = 189 }, { ["y"] = 9, ["x"] = 5, ["name"] = "cottages:roof_straw", ["z"] = 16, ["meta"] = { ["inventory"] = {  }, ["fields"] = {  } }, ["param2"] = 1, ["param1"] = 205 }, { ["y"] = 9, ["x"] = 5, ["name"] = "cottages:roof_straw", ["z"] = 17, ["meta"] = { ["inventory"] = {  }, ["fields"] = {  } }, ["param2"] = 1, ["param1"] = 189 }, { ["y"] = 9, ["x"] = 5, ["name"] = "cottages:roof_straw", ["z"] = 18, ["meta"] = { ["inventory"] = {  }, ["fields"] = {  } }, ["param2"] = 1, ["param1"] = 173 }, { ["y"] = 9, ["x"] = 5, ["name"] = "cottages:roof_straw", ["z"] = 19, ["meta"] = { ["inventory"] = {  }, ["fields"] = {  } }, ["param2"] = 1, ["param1"] = 189 }, { ["y"] = 9, ["x"] = 5, ["name"] = "cottages:roof_straw", ["z"] = 20, ["meta"] = { ["inventory"] = {  }, ["fields"] = {  } }, ["param2"] = 1, ["param1"] = 205 }, { ["y"] = 9, ["x"] = 5, ["name"] = "cottages:roof_straw", ["z"] = 21, ["meta"] = { ["inventory"] = {  }, ["fields"] = {  } }, ["param2"] = 1, ["param1"] = 189 }, { ["y"] = 9, ["x"] = 5, ["name"] = "cottages:roof_straw", ["z"] = 22, ["meta"] = { ["inventory"] = {  }, ["fields"] = {  } }, ["param2"] = 1, ["param1"] = 205 }, { ["y"] = 9, ["x"] = 5, ["name"] = "cottages:roof_connector_straw", ["z"] = 23, ["meta"] = { ["inventory"] = {  }, ["fields"] = {  } }, ["param2"] = 1, ["param1"] = 189 }, { ["y"] = 10, ["x"] = 5, ["name"] = "cottages:glass_pane", ["z"] = 4, ["meta"] = { ["inventory"] = {  }, ["fields"] = {  } }, ["param2"] = 2, ["param1"] = 188 }, { ["y"] = 10, ["x"] = 5, ["name"] = "cottages:loam", ["z"] = 9, ["meta"] = { ["inventory"] = {  }, ["fields"] = {  } }, ["param2"] = 0, ["param1"] = 0 }, { ["y"] = 11, ["x"] = 5, ["name"] = "cottages:glass_pane", ["z"] = 4, ["meta"] = { ["inventory"] = {  }, ["fields"] = {  } }, ["param2"] = 2, ["param1"] = 188 }, { ["y"] = 11, ["x"] = 5, ["name"] = "stairs:slab_wood", ["z"] = 5, ["meta"] = { ["inventory"] = {  }, ["fields"] = {  } }, ["param2"] = 0, ["param1"] = 204 }, { ["y"] = 11, ["x"] = 5, ["name"] = "cottages:loam", ["z"] = 9, ["meta"] = { ["inventory"] = {  }, ["fields"] = {  } }, ["param2"] = 0, ["param1"] = 0 }, { ["y"] = 12, ["x"] = 5, ["name"] = "cottages:roof_straw", ["z"] = 3, ["meta"] = { ["inventory"] = {  }, ["fields"] = {  } }, ["param2"] = 0, ["param1"] = 157 }, { ["y"] = 12, ["x"] = 5, ["name"] = "cottages:loam", ["z"] = 4, ["meta"] = { ["inventory"] = {  }, ["fields"] = {  } }, ["param2"] = 0, ["param1"] = 0 }, { ["y"] = 12, ["x"] = 5, ["name"] = "default:torch", ["z"] = 5, ["meta"] = { ["inventory"] = {  }, ["fields"] = {  } }, ["param2"] = 5, ["param1"] = 0 }, { ["y"] = 12, ["x"] = 5, ["name"] = "cottages:loam", ["z"] = 9, ["meta"] = { ["inventory"] = {  }, ["fields"] = {  } }, ["param2"] = 0, ["param1"] = 0 }, { ["y"] = 12, ["x"] = 5, ["name"] = "cottages:roof_straw", ["z"] = 10, ["meta"] = { ["inventory"] = {  }, ["fields"] = {  } }, ["param2"] = 2, ["param1"] = 141 }, { ["y"] = 13, ["x"] = 5, ["name"] = "cottages:roof_connector_straw", ["z"] = 4, ["meta"] = { ["inventory"] = {  }, ["fields"] = {  } }, ["param2"] = 0, ["param1"] = 189 }, { ["y"] = 13, ["x"] = 5, ["name"] = "default:steelblock", ["z"] = 6, ["meta"] = { ["inventory"] = {  }, ["fields"] = {  } }, ["param2"] = 0, ["param1"] = 0 }, { ["y"] = 13, ["x"] = 5, ["name"] = "cottages:table", ["z"] = 7, ["meta"] = { ["inventory"] = {  }, ["fields"] = {  } }, ["param2"] = 1, ["param1"] = 204 }, { ["y"] = 13, ["x"] = 5, ["name"] = "cottages:roof_connector_straw", ["z"] = 9, ["meta"] = { ["inventory"] = {  }, ["fields"] = {  } }, ["param2"] = 2, ["param1"] = 173 }, { ["y"] = 14, ["x"] = 5, ["name"] = "cottages:roof_connector_straw", ["z"] = 4, ["meta"] = { ["inventory"] = {  }, ["fields"] = {  } }, ["param2"] = 0, ["param1"] = 189 }, { ["y"] = 14, ["x"] = 5, ["name"] = "default:fence_wood", ["z"] = 6, ["meta"] = { ["inventory"] = {  }, ["fields"] = {  } }, ["param2"] = 0, ["param1"] = 204 }, { ["y"] = 14, ["x"] = 5, ["name"] = "default:torch", ["z"] = 7, ["meta"] = { ["inventory"] = {  }, ["fields"] = {  } }, ["param2"] = 1, ["param1"] = 0 }, { ["y"] = 14, ["x"] = 5, ["name"] = "cottages:roof_connector_straw", ["z"] = 9, ["meta"] = { ["inventory"] = {  }, ["fields"] = {  } }, ["param2"] = 2, ["param1"] = 189 }, { ["y"] = 15, ["x"] = 5, ["name"] = "cottages:roof_connector_straw", ["z"] = 5, ["meta"] = { ["inventory"] = {  }, ["fields"] = {  } }, ["param2"] = 0, ["param1"] = 189 }, { ["y"] = 15, ["x"] = 5, ["name"] = "default:fence_wood", ["z"] = 6, ["meta"] = { ["inventory"] = {  }, ["fields"] = {  } }, ["param2"] = 0, ["param1"] = 188 }, { ["y"] = 15, ["x"] = 5, ["name"] = "cottages:roof_connector_straw", ["z"] = 8, ["meta"] = { ["inventory"] = {  }, ["fields"] = {  } }, ["param2"] = 2, ["param1"] = 189 }, { ["y"] = 16, ["x"] = 5, ["name"] = "cottages:roof_connector_straw", ["z"] = 5, ["meta"] = { ["inventory"] = {  }, ["fields"] = {  } }, ["param2"] = 0, ["param1"] = 189 }, { ["y"] = 16, ["x"] = 5, ["name"] = "default:fence_wood", ["z"] = 6, ["meta"] = { ["inventory"] = {  }, ["fields"] = {  } }, ["param2"] = 0, ["param1"] = 204 }, { ["y"] = 16, ["x"] = 5, ["name"] = "default:torch", ["z"] = 7, ["meta"] = { ["inventory"] = {  }, ["fields"] = {  } }, ["param2"] = 4, ["param1"] = 0 }, { ["y"] = 16, ["x"] = 5, ["name"] = "cottages:roof_connector_straw", ["z"] = 8, ["meta"] = { ["inventory"] = {  }, ["fields"] = {  } }, ["param2"] = 2, ["param1"] = 205 }, { ["y"] = 17, ["x"] = 5, ["name"] = "cottages:roof_connector_straw", ["z"] = 6, ["meta"] = { ["inventory"] = {  }, ["fields"] = {  } }, ["param2"] = 1, ["param1"] = 189 }, { ["y"] = 17, ["x"] = 5, ["name"] = "cottages:roof_connector_straw", ["z"] = 7, ["meta"] = { ["inventory"] = {  }, ["fields"] = {  } }, ["param2"] = 1, ["param1"] = 205 }, { ["y"] = 0, ["x"] = 6, ["name"] = "stairs:slab_cobble", ["z"] = 0, ["meta"] = { ["inventory"] = {  }, ["fields"] = {  } }, ["param2"] = 0, ["param1"] = 125 }, { ["y"] = 0, ["x"] = 6, ["name"] = "stairs:slab_cobble", ["z"] = 1, ["meta"] = { ["inventory"] = {  }, ["fields"] = {  } }, ["param2"] = 0, ["param1"] = 141 }, { ["y"] = 0, ["x"] = 6, ["name"] = "stairs:slab_cobble", ["z"] = 2, ["meta"] = { ["inventory"] = {  }, ["fields"] = {  } }, ["param2"] = 0, ["param1"] = 157 }, { ["y"] = 0, ["x"] = 6, ["name"] = "stairs:slab_cobble", ["z"] = 3, ["meta"] = { ["inventory"] = {  }, ["fields"] = {  } }, ["param2"] = 0, ["param1"] = 172 }, { ["y"] = 0, ["x"] = 6, ["name"] = "stairs:stair_cobble", ["z"] = 4, ["meta"] = { ["inventory"] = {  }, ["fields"] = {  } }, ["param2"] = 0, ["param1"] = 155 }, { ["y"] = 0, ["x"] = 6, ["name"] = "stairs:slab_cobble", ["z"] = 5, ["meta"] = { ["inventory"] = {  }, ["fields"] = {  } }, ["param2"] = 0, ["param1"] = 170 }, { ["y"] = 0, ["x"] = 6, ["name"] = "stairs:slab_cobble", ["z"] = 6, ["meta"] = { ["inventory"] = {  }, ["fields"] = {  } }, ["param2"] = 0, ["param1"] = 153 }, { ["y"] = 0, ["x"] = 6, ["name"] = "stairs:slab_cobble", ["z"] = 7, ["meta"] = { ["inventory"] = {  }, ["fields"] = {  } }, ["param2"] = 0, ["param1"] = 136 }, { ["y"] = 0, ["x"] = 6, ["name"] = "stairs:slab_cobble", ["z"] = 8, ["meta"] = { ["inventory"] = {  }, ["fields"] = {  } }, ["param2"] = 0, ["param1"] = 136 }, { ["y"] = 0, ["x"] = 6, ["name"] = "stairs:slab_cobble", ["z"] = 9, ["meta"] = { ["inventory"] = {  }, ["fields"] = {  } }, ["param2"] = 0, ["param1"] = 153 }, { ["y"] = 0, ["x"] = 6, ["name"] = "stairs:slab_cobble", ["z"] = 10, ["meta"] = { ["inventory"] = {  }, ["fields"] = {  } }, ["param2"] = 0, ["param1"] = 170 }, { ["y"] = 0, ["x"] = 6, ["name"] = "stairs:slab_cobble", ["z"] = 11, ["meta"] = { ["inventory"] = {  }, ["fields"] = {  } }, ["param2"] = 0, ["param1"] = 153 }, { ["y"] = 0, ["x"] = 6, ["name"] = "stairs:slab_cobble", ["z"] = 12, ["meta"] = { ["inventory"] = {  }, ["fields"] = {  } }, ["param2"] = 0, ["param1"] = 136 }, { ["y"] = 0, ["x"] = 6, ["name"] = "stairs:slab_cobble", ["z"] = 13, ["meta"] = { ["inventory"] = {  }, ["fields"] = {  } }, ["param2"] = 0, ["param1"] = 136 }, { ["y"] = 0, ["x"] = 6, ["name"] = "stairs:slab_cobble", ["z"] = 14, ["meta"] = { ["inventory"] = {  }, ["fields"] = {  } }, ["param2"] = 0, ["param1"] = 119 }, { ["y"] = 0, ["x"] = 6, ["name"] = "stairs:slab_cobble", ["z"] = 15, ["meta"] = { ["inventory"] = {  }, ["fields"] = {  } }, ["param2"] = 0, ["param1"] = 136 }, { ["y"] = 0, ["x"] = 6, ["name"] = "stairs:slab_cobble", ["z"] = 16, ["meta"] = { ["inventory"] = {  }, ["fields"] = {  } }, ["param2"] = 0, ["param1"] = 119 }, { ["y"] = 0, ["x"] = 6, ["name"] = "stairs:slab_cobble", ["z"] = 17, ["meta"] = { ["inventory"] = {  }, ["fields"] = {  } }, ["param2"] = 0, ["param1"] = 136 }, { ["y"] = 0, ["x"] = 6, ["name"] = "stairs:slab_cobble", ["z"] = 18, ["meta"] = { ["inventory"] = {  }, ["fields"] = {  } }, ["param2"] = 0, ["param1"] = 119 }, { ["y"] = 0, ["x"] = 6, ["name"] = "stairs:slab_cobble", ["z"] = 19, ["meta"] = { ["inventory"] = {  }, ["fields"] = {  } }, ["param2"] = 0, ["param1"] = 136 }, { ["y"] = 0, ["x"] = 6, ["name"] = "stairs:slab_cobble", ["z"] = 20, ["meta"] = { ["inventory"] = {  }, ["fields"] = {  } }, ["param2"] = 0, ["param1"] = 153 }, { ["y"] = 0, ["x"] = 6, ["name"] = "stairs:slab_cobble", ["z"] = 21, ["meta"] = { ["inventory"] = {  }, ["fields"] = {  } }, ["param2"] = 0, ["param1"] = 170 }, { ["y"] = 0, ["x"] = 6, ["name"] = "default:cobble", ["z"] = 22, ["meta"] = { ["inventory"] = {  }, ["fields"] = {  } }, ["param2"] = 0, ["param1"] = 0 }, { ["y"] = 0, ["x"] = 6, ["name"] = "default:cobble", ["z"] = 23, ["meta"] = { ["inventory"] = {  }, ["fields"] = {  } }, ["param2"] = 0, ["param1"] = 0 }, { ["y"] = 0, ["x"] = 6, ["name"] = "default:cobble", ["z"] = 24, ["meta"] = { ["inventory"] = {  }, ["fields"] = {  } }, ["param2"] = 0, ["param1"] = 0 }, { ["y"] = 0, ["x"] = 6, ["name"] = "default:cobble", ["z"] = 25, ["meta"] = { ["inventory"] = {  }, ["fields"] = {  } }, ["param2"] = 0, ["param1"] = 0 }, { ["y"] = 1, ["x"] = 6, ["name"] = "cottages:half_door_inverted", ["z"] = 4, ["meta"] = { ["inventory"] = {  }, ["fields"] = {  } }, ["param2"] = 2, ["param1"] = 172 }, { ["y"] = 1, ["x"] = 6, ["name"] = "default:cobble", ["z"] = 22, ["meta"] = { ["inventory"] = {  }, ["fields"] = {  } }, ["param2"] = 0, ["param1"] = 0 }, { ["y"] = 1, ["x"] = 6, ["name"] = "cottages:loam", ["z"] = 25, ["meta"] = { ["inventory"] = {  }, ["fields"] = {  } }, ["param2"] = 0, ["param1"] = 0 }, { ["y"] = 2, ["x"] = 6, ["name"] = "cottages:half_door_inverted", ["z"] = 4, ["meta"] = { ["inventory"] = {  }, ["fields"] = {  } }, ["param2"] = 2, ["param1"] = 188 }, { ["y"] = 2, ["x"] = 6, ["name"] = "default:torch", ["z"] = 22, ["meta"] = { ["inventory"] = {  }, ["fields"] = {  } }, ["param2"] = 1, ["param1"] = 0 }, { ["y"] = 2, ["x"] = 6, ["name"] = "cottages:glass_pane", ["z"] = 25, ["meta"] = { ["inventory"] = {  }, ["fields"] = {  } }, ["param2"] = 0, ["param1"] = 189 }, { ["y"] = 3, ["x"] = 6, ["name"] = "cottages:loam", ["z"] = 4, ["meta"] = { ["inventory"] = {  }, ["fields"] = {  } }, ["param2"] = 0, ["param1"] = 0 }, { ["y"] = 3, ["x"] = 6, ["name"] = "default:ladder", ["z"] = 6, ["meta"] = { ["inventory"] = {  }, ["fields"] = {  } }, ["param2"] = 4, ["param1"] = 170 }, { ["y"] = 3, ["x"] = 6, ["name"] = "stairs:stair_wood", ["z"] = 7, ["meta"] = { ["inventory"] = {  }, ["fields"] = {  } }, ["param2"] = 2, ["param1"] = 170 }, { ["y"] = 3, ["x"] = 6, ["name"] = "stairs:slab_wood", ["z"] = 8, ["meta"] = { ["inventory"] = {  }, ["fields"] = {  } }, ["param2"] = 0, ["param1"] = 170 }, { ["y"] = 3, ["x"] = 6, ["name"] = "cottages:loam", ["z"] = 9, ["meta"] = { ["inventory"] = {  }, ["fields"] = {  } }, ["param2"] = 0, ["param1"] = 0 }, { ["y"] = 3, ["x"] = 6, ["name"] = "cottages:glass_pane", ["z"] = 25, ["meta"] = { ["inventory"] = {  }, ["fields"] = {  } }, ["param2"] = 0, ["param1"] = 173 }, { ["y"] = 4, ["x"] = 6, ["name"] = "cottages:loam", ["z"] = 4, ["meta"] = { ["inventory"] = {  }, ["fields"] = {  } }, ["param2"] = 0, ["param1"] = 0 }, { ["y"] = 4, ["x"] = 6, ["name"] = "default:ladder", ["z"] = 6, ["meta"] = { ["inventory"] = {  }, ["fields"] = {  } }, ["param2"] = 4, ["param1"] = 170 }, { ["y"] = 4, ["x"] = 6, ["name"] = "cottages:bench", ["z"] = 7, ["meta"] = { ["inventory"] = {  }, ["fields"] = {  } }, ["param2"] = 2, ["param1"] = 187 }, { ["y"] = 4, ["x"] = 6, ["name"] = "default:fence_wood", ["z"] = 9, ["meta"] = { ["inventory"] = {  }, ["fields"] = {  } }, ["param2"] = 0, ["param1"] = 170 }, { ["y"] = 4, ["x"] = 6, ["name"] = "cottages:glass_pane", ["z"] = 25, ["meta"] = { ["inventory"] = {  }, ["fields"] = {  } }, ["param2"] = 0, ["param1"] = 157 }, { ["y"] = 5, ["x"] = 6, ["name"] = "cottages:loam", ["z"] = 4, ["meta"] = { ["inventory"] = {  }, ["fields"] = {  } }, ["param2"] = 0, ["param1"] = 0 }, { ["y"] = 5, ["x"] = 6, ["name"] = "stairs:stair_wood", ["z"] = 5, ["meta"] = { ["inventory"] = {  }, ["fields"] = {  } }, ["param2"] = 3, ["param1"] = 187 }, { ["y"] = 5, ["x"] = 6, ["name"] = "default:ladder", ["z"] = 7, ["meta"] = { ["inventory"] = {  }, ["fields"] = {  } }, ["param2"] = 5, ["param1"] = 187 }, { ["y"] = 5, ["x"] = 6, ["name"] = "cottages:loam", ["z"] = 24, ["meta"] = { ["inventory"] = {  }, ["fields"] = {  } }, ["param2"] = 0, ["param1"] = 0 }, { ["y"] = 5, ["x"] = 6, ["name"] = "cottages:roof_connector_straw", ["z"] = 25, ["meta"] = { ["inventory"] = {  }, ["fields"] = {  } }, ["param2"] = 2, ["param1"] = 141 }, { ["y"] = 6, ["x"] = 6, ["name"] = "cottages:loam", ["z"] = 4, ["meta"] = { ["inventory"] = {  }, ["fields"] = {  } }, ["param2"] = 0, ["param1"] = 0 }, { ["y"] = 6, ["x"] = 6, ["name"] = "default:ladder", ["z"] = 6, ["meta"] = { ["inventory"] = {  }, ["fields"] = {  } }, ["param2"] = 1, ["param1"] = 187 }, { ["y"] = 6, ["x"] = 6, ["name"] = "cottages:loam", ["z"] = 9, ["meta"] = { ["inventory"] = {  }, ["fields"] = {  } }, ["param2"] = 0, ["param1"] = 0 }, { ["y"] = 6, ["x"] = 6, ["name"] = "cottages:loam", ["z"] = 23, ["meta"] = { ["inventory"] = {  }, ["fields"] = {  } }, ["param2"] = 0, ["param1"] = 0 }, { ["y"] = 6, ["x"] = 6, ["name"] = "cottages:roof_straw", ["z"] = 24, ["meta"] = { ["inventory"] = {  }, ["fields"] = {  } }, ["param2"] = 2, ["param1"] = 109 }, { ["y"] = 7, ["x"] = 6, ["name"] = "cottages:glass_pane", ["z"] = 4, ["meta"] = { ["inventory"] = {  }, ["fields"] = {  } }, ["param2"] = 2, ["param1"] = 172 }, { ["y"] = 7, ["x"] = 6, ["name"] = "cottages:loam", ["z"] = 9, ["meta"] = { ["inventory"] = {  }, ["fields"] = {  } }, ["param2"] = 0, ["param1"] = 0 }, { ["y"] = 7, ["x"] = 6, ["name"] = "cottages:loam", ["z"] = 23, ["meta"] = { ["inventory"] = {  }, ["fields"] = {  } }, ["param2"] = 0, ["param1"] = 0 }, { ["y"] = 8, ["x"] = 6, ["name"] = "cottages:glass_pane", ["z"] = 4, ["meta"] = { ["inventory"] = {  }, ["fields"] = {  } }, ["param2"] = 2, ["param1"] = 188 }, { ["y"] = 8, ["x"] = 6, ["name"] = "cottages:loam", ["z"] = 9, ["meta"] = { ["inventory"] = {  }, ["fields"] = {  } }, ["param2"] = 0, ["param1"] = 0 }, { ["y"] = 8, ["x"] = 6, ["name"] = "default:torch", ["z"] = 10, ["meta"] = { ["inventory"] = {  }, ["fields"] = {  } }, ["param2"] = 2, ["param1"] = 0 }, { ["y"] = 8, ["x"] = 6, ["name"] = "default:torch", ["z"] = 14, ["meta"] = { ["inventory"] = {  }, ["fields"] = {  } }, ["param2"] = 2, ["param1"] = 0 }, { ["y"] = 8, ["x"] = 6, ["name"] = "default:torch", ["z"] = 19, ["meta"] = { ["inventory"] = {  }, ["fields"] = {  } }, ["param2"] = 2, ["param1"] = 0 }, { ["y"] = 8, ["x"] = 6, ["name"] = "cottages:loam", ["z"] = 23, ["meta"] = { ["inventory"] = {  }, ["fields"] = {  } }, ["param2"] = 0, ["param1"] = 0 }, { ["y"] = 9, ["x"] = 6, ["name"] = "cottages:loam", ["z"] = 4, ["meta"] = { ["inventory"] = {  }, ["fields"] = {  } }, ["param2"] = 0, ["param1"] = 0 }, { ["y"] = 9, ["x"] = 6, ["name"] = "cottages:loam", ["z"] = 9, ["meta"] = { ["inventory"] = {  }, ["fields"] = {  } }, ["param2"] = 0, ["param1"] = 0 }, { ["y"] = 9, ["x"] = 6, ["name"] = "cottages:roof_straw", ["z"] = 10, ["meta"] = { ["inventory"] = {  }, ["fields"] = {  } }, ["param2"] = 3, ["param1"] = 204 }, { ["y"] = 9, ["x"] = 6, ["name"] = "cottages:roof_straw", ["z"] = 11, ["meta"] = { ["inventory"] = {  }, ["fields"] = {  } }, ["param2"] = 3, ["param1"] = 189 }, { ["y"] = 9, ["x"] = 6, ["name"] = "cottages:roof_straw", ["z"] = 12, ["meta"] = { ["inventory"] = {  }, ["fields"] = {  } }, ["param2"] = 3, ["param1"] = 189 }, { ["y"] = 9, ["x"] = 6, ["name"] = "cottages:roof_straw", ["z"] = 13, ["meta"] = { ["inventory"] = {  }, ["fields"] = {  } }, ["param2"] = 3, ["param1"] = 189 }, { ["y"] = 9, ["x"] = 6, ["name"] = "cottages:roof_straw", ["z"] = 14, ["meta"] = { ["inventory"] = {  }, ["fields"] = {  } }, ["param2"] = 3, ["param1"] = 205 },