return { { ["y"] = 0, ["x"] = 0, ["name"] = "stairs:slab_cobble", ["z"] = 1, ["meta"] = { ["inventory"] = {  }, ["fields"] = {  } }, ["param2"] = 0, ["param1"] = 45 }, { ["y"] = 0, ["x"] = 0, ["name"] = "stairs:slab_cobble", ["z"] = 2, ["meta"] = { ["inventory"] = {  }, ["fields"] = {  } }, ["param2"] = 0, ["param1"] = 61 }, { ["y"] = 0, ["x"] = 0, ["name"] = "stairs:slab_cobble", ["z"] = 3, ["meta"] = { ["inventory"] = {  }, ["fields"] = {  } }, ["param2"] = 0, ["param1"] = 45 }, { ["y"] = 0, ["x"] = 0, ["name"] = "stairs:slab_cobble", ["z"] = 4, ["meta"] = { ["inventory"] = {  }, ["fields"] = {  } }, ["param2"] = 0, ["param1"] = 61 }, { ["y"] = 0, ["x"] = 1, ["name"] = "stairs:slab_cobble", ["z"] = 0, ["meta"] = { ["inventory"] = {  }, ["fields"] = {  } }, ["param2"] = 0, ["param1"] = 45 }, { ["y"] = 0, ["x"] = 1, ["name"] = "stairs:slab_cobble", ["z"] = 1, ["meta"] = { ["inventory"] = {  }, ["fields"] = {  } }, ["param2"] = 0, ["param1"] = 28 }, { ["y"] = 0, ["x"] = 1, ["name"] = "default:cobble", ["z"] = 2, ["meta"] = { ["inventory"] = {  }, ["fields"] = {  } }, ["param2"] = 0, ["param1"] = 0 }, { ["y"] = 0, ["x"] = 1, ["name"] = "default:cobble", ["z"] = 3, ["meta"] = { ["inventory"] = {  }, ["fields"] = {  } }, ["param2"] = 0, ["param1"] = 0 }, { ["y"] = 0, ["x"] = 1, ["name"] = "stairs:slab_cobble", ["z"] = 4, ["meta"] = { ["inventory"] = {  }, ["fields"] = {  } }, ["param2"] = 0, ["param1"] = 44 }, { ["y"] = 0, ["x"] = 1, ["name"] = "stairs:slab_cobble", ["z"] = 5, ["meta"] = { ["inventory"] = {  }, ["fields"] = {  } }, ["param2"] = 0, ["param1"] = 29 }, { ["y"] = 3, ["x"] = 1, ["name"] = "cottages:roof_flat_straw", ["z"] = 0, ["meta"] = { ["inventory"] = {  }, ["fields"] = {  } }, ["param2"] = 0, ["param1"] = 61 }, { ["y"] = 3, ["x"] = 1, ["name"] = "cottages:roof_straw", ["z"] = 1, ["meta"] = { ["inventory"] = {  }, ["fields"] = {  } }, ["param2"] = 1, ["param1"] = 45 }, { ["y"] = 3, ["x"] = 1, ["name"] = "cottages:roof_straw", ["z"] = 2, ["meta"] = { ["inventory"] = {  }, ["fields"] = {  } }, ["param2"] = 1, ["param1"] = 61 }, { ["y"] = 3, ["x"] = 1, ["name"] = "cottages:roof_straw", ["z"] = 3, ["meta"] = { ["inventory"] = {  }, ["fields"] = {  } }, ["param2"] = 1, ["param1"] = 45 }, { ["y"] = 3, ["x"] = 1, ["name"] = "cottages:roof_straw", ["z"] = 4, ["meta"] = { ["inventory"] = {  }, ["fields"] = {  } }, ["param2"] = 1, ["param1"] = 61 }, { ["y"] = 3, ["x"] = 1, ["name"] = "cottages:roof_flat_straw", ["z"] = 5, ["meta"] = { ["inventory"] = {  }, ["fields"] = {  } }, ["param2"] = 2, ["param1"] = 45 }, { ["y"] = 0, ["x"] = 2, ["name"] = "stairs:slab_cobble", ["z"] = 0, ["meta"] = { ["inventory"] = {  }, ["fields"] = {  } }, ["param2"] = 0, ["param1"] = 29 }, { ["y"] = 0, ["x"] = 2, ["name"] = "default:cobble", ["z"] = 1, ["meta"] = { ["inventory"] = {  }, ["fields"] = {  } }, ["param2"] = 0, ["param1"] = 0 }, { ["y"] = 0, ["x"] = 2, ["name"] = "default:water_source", ["z"] = 2, ["meta"] = { ["inventory"] = {  }, ["fields"] = {  } }, ["param2"] = 0, ["param1"] = 27 }, { ["y"] = 0, ["x"] = 2, ["name"] = "default:water_source", ["z"] = 3, ["meta"] = { ["inventory"] = {  }, ["fields"] = {  } }, ["param2"] = 0, ["param1"] = 11 }, { ["y"] = 0, ["x"] = 2, ["name"] = "default:cobble", ["z"] = 4, ["meta"] = { ["inventory"] = {  }, ["fields"] = {  } }, ["param2"] = 0, ["param1"] = 0 }, { ["y"] = 0, ["x"] = 2, ["name"] = "stairs:slab_cobble", ["z"] = 5, ["meta"] = { ["inventory"] = {  }, ["fields"] = {  } }, ["param2"] = 0, ["param1"] = 13 }, { ["y"] = 1, ["x"] = 2, ["name"] = "default:fence_wood", ["z"] = 1, ["meta"] = { ["inventory"] = {  }, ["fields"] = {  } }, ["param2"] = 0, ["param1"] = 28 }, { ["y"] = 1, ["x"] = 2, ["name"] = "default:fence_wood", ["z"] = 4, ["meta"] = { ["inventory"] = {  }, ["fields"] = {  } }, ["param2"] = 0, ["param1"] = 44 }, { ["y"] = 2, ["x"] = 2, ["name"] = "default:fence_wood", ["z"] = 1, ["meta"] = { ["inventory"] = {  }, ["fields"] = {  } }, ["param2"] = 0, ["param1"] = 44 }, { ["y"] = 2, ["x"] = 2, ["name"] = "default:fence_wood", ["z"] = 2, ["meta"] = { ["inventory"] = {  }, ["fields"] = {  } }, ["param2"] = 0, ["param1"] = 60 }, { ["y"] = 2, ["x"] = 2, ["name"] = "default:fence_wood", ["z"] = 3, ["meta"] = { ["inventory"] = {  }, ["fields"] = {  } }, ["param2"] = 0, ["param1"] = 44 }, { ["y"] = 2, ["x"] = 2, ["name"] = "default:fence_wood", ["z"] = 4, ["meta"] = { ["inventory"] = {  }, ["fields"] = {  } }, ["param2"] = 0, ["param1"] = 60 }, { ["y"] = 3, ["x"] = 2, ["name"] = "cottages:roof_straw", ["z"] = 0, ["meta"] = { ["inventory"] = {  }, ["fields"] = {  } }, ["param2"] = 0, ["param1"] = 45 }, { ["y"] = 3, ["x"] = 2, ["name"] = "default:fence_wood", ["z"] = 1, ["meta"] = { ["inventory"] = {  }, ["fields"] = {  } }, ["param2"] = 0, ["param1"] = 28 }, { ["y"] = 3, ["x"] = 2, ["name"] = "default:fence_wood", ["z"] = 4, ["meta"] = { ["inventory"] = {  }, ["fields"] = {  } }, ["param2"] = 0, ["param1"] = 44 }, { ["y"] = 3, ["x"] = 2, ["name"] = "cottages:roof_straw", ["z"] = 5, ["meta"] = { ["inventory"] = {  }, ["fields"] = {  } }, ["param2"] = 2, ["param1"] = 29 }, { ["y"] = 4, ["x"] = 2, ["name"] = "cottages:roof_flat_straw", ["z"] = 1, ["meta"] = { ["inventory"] = {  }, ["fields"] = {  } }, ["param2"] = 0, ["param1"] = 13 }, { ["y"] = 4, ["x"] = 2, ["name"] = "cottages:roof_flat_straw", ["z"] = 2, ["meta"] = { ["inventory"] = {  }, ["fields"] = {  } }, ["param2"] = 0, ["param1"] = 29 }, { ["y"] = 4, ["x"] = 2, ["name"] = "cottages:roof_flat_straw", ["z"] = 3, ["meta"] = { ["inventory"] = {  }, ["fields"] = {  } }, ["param2"] = 0, ["param1"] = 13 }, { ["y"] = 4, ["x"] = 2, ["name"] = "cottages:roof_flat_straw", ["z"] = 4, ["meta"] = { ["inventory"] = {  }, ["fields"] = {  } }, ["param2"] = 0, ["param1"] = 29 }, { ["y"] = 0, ["x"] = 3, ["name"] = "stairs:slab_cobble", ["z"] = 0, ["meta"] = { ["inventory"] = {  }, ["fields"] = {  } }, ["param2"] = 0, ["param1"] = 13 }, { ["y"] = 0, ["x"] = 3, ["name"] = "stairs:slab_cobble", ["z"] = 1, ["meta"] = { ["inventory"] = {  }, ["fields"] = {  } }, ["param2"] = 0, ["param1"] = 12 }, { ["y"] = 0, ["x"] = 3, ["name"] = "default:cobble", ["z"] = 2, ["meta"] = { ["inventory"] = {  }, ["fields"] = {  } }, ["param2"] = 0, ["param1"] = 0 }, { ["y"] = 0, ["x"] = 3, ["name"] = "default:cobble", ["z"] = 3, ["meta"] = { ["inventory"] = {  }, ["fields"] = {  } }, ["param2"] = 0, ["param1"] = 0 }, { ["y"] = 0, ["x"] = 3, ["name"] = "stairs:slab_cobble", ["z"] = 4, ["meta"] = { ["inventory"] = {  }, ["fields"] = {  } }, ["param2"] = 0, ["param1"] = 12 }, { ["y"] = 0, ["x"] = 3, ["name"] = "stairs:slab_cobble", ["z"] = 5, ["meta"] = { ["inventory"] = {  }, ["fields"] = {  } }, ["param2"] = 0, ["param1"] = 13 }, { ["y"] = 3, ["x"] = 3, ["name"] = "cottages:roof_flat_straw", ["z"] = 0, ["meta"] = { ["inventory"] = {  }, ["fields"] = {  } }, ["param2"] = 0, ["param1"] = 29 }, { ["y"] = 3, ["x"] = 3, ["name"] = "cottages:roof_straw", ["z"] = 1, ["meta"] = { ["inventory"] = {  }, ["fields"] = {  } }, ["param2"] = 3, ["param1"] = 13 }, { ["y"] = 3, ["x"] = 3, ["name"] = "cottages:roof_straw", ["z"] = 2, ["meta"] = { ["inventory"] = {  }, ["fields"] = {  } }, ["param2"] = 3, ["param1"] = 29 }, { ["y"] = 3, ["x"] = 3, ["name"] = "cottages:roof_straw", ["z"] = 3, ["meta"] = { ["inventory"] = {  }, ["fields"] = {  } }, ["param2"] = 3, ["param1"] = 13 }, { ["y"] = 3, ["x"] = 3, ["name"] = "cottages:roof_straw", ["z"] = 4, ["meta"] = { ["inventory"] = {  }, ["fields"] = {  } }, ["param2"] = 3, ["param1"] = 29 }, { ["y"] = 3, ["x"] = 3, ["name"] = "cottages:roof_flat_straw", ["z"] = 5, ["meta"] = { ["inventory"] = {  }, ["fields"] = {  } }, ["param2"] = 2, ["param1"] = 45 }, { ["y"] = 0, ["x"] = 4, ["name"] = "stairs:slab_cobble", ["z"] = 1, ["meta"] = { ["inventory"] = {  }, ["fields"] = {  } }, ["param2"] = 0, ["param1"] = 13 }, { ["y"] = 0, ["x"] = 4, ["name"] = "stairs:slab_cobble", ["z"] = 2, ["meta"] = { ["inventory"] = {  }, ["fields"] = {  } }, ["param2"] = 0, ["param1"] = 13 }, { ["y"] = 0, ["x"] = 4, ["name"] = "stairs:slab_cobble", ["z"] = 3, ["meta"] = { ["inventory"] = {  }, ["fields"] = {  } }, ["param2"] = 0, ["param1"] = 13 }, { ["y"] = 0, ["x"] = 4, ["name"] = "stairs:slab_cobble", ["z"] = 4, ["meta"] = { ["inventory"] = {  }, ["fields"] = {  } }, ["param2"] = 0, ["param1"] = 13 } }
