return { { ["y"] = 0, ["x"] = 0, ["name"] = "stairs:slab_cobble", ["z"] = 1, ["meta"] = { ["inventory"] = {  }, ["fields"] = {  } }, ["param2"] = 0, ["param1"] = 61 }, { ["y"] = 0, ["x"] = 0, ["name"] = "default:cobble", ["z"] = 2, ["meta"] = { ["inventory"] = {  }, ["fields"] = {  } }, ["param2"] = 0, ["param1"] = 0 }, { ["y"] = 0, ["x"] = 0, ["name"] = "stairs:slab_cobble", ["z"] = 3, ["meta"] = { ["inventory"] = {  }, ["fields"] = {  } }, ["param2"] = 0, ["param1"] = 61 }, { ["y"] = 3, ["x"] = 0, ["name"] = "cottages:roof_flat_straw", ["z"] = 0, ["meta"] = { ["inventory"] = {  }, ["fields"] = {  } }, ["param2"] = 1, ["param1"] = 61 }, { ["y"] = 3, ["x"] = 0, ["name"] = "cottages:roof_straw", ["z"] = 1, ["meta"] = { ["inventory"] = {  }, ["fields"] = {  } }, ["param2"] = 1, ["param1"] = 77 }, { ["y"] = 3, ["x"] = 0, ["name"] = "cottages:roof_straw", ["z"] = 2, ["meta"] = { ["inventory"] = {  }, ["fields"] = {  } }, ["param2"] = 1, ["param1"] = 93 }, { ["y"] = 3, ["x"] = 0, ["name"] = "cottages:roof_straw", ["z"] = 3, ["meta"] = { ["inventory"] = {  }, ["fields"] = {  } }, ["param2"] = 1, ["param1"] = 109 }, { ["y"] = 3, ["x"] = 0, ["name"] = "cottages:roof_flat_straw", ["z"] = 4, ["meta"] = { ["inventory"] = {  }, ["fields"] = {  } }, ["param2"] = 1, ["param1"] = 93 }, { ["y"] = 0, ["x"] = 1, ["name"] = "default:cobble", ["z"] = 1, ["meta"] = { ["inventory"] = {  }, ["fields"] = {  } }, ["param2"] = 0, ["param1"] = 0 }, { ["y"] = 0, ["x"] = 1, ["name"] = "default:water_source", ["z"] = 2, ["meta"] = { ["inventory"] = {  }, ["fields"] = {  } }, ["param2"] = 0, ["param1"] = 59 }, { ["y"] = 0, ["x"] = 1, ["name"] = "default:cobble", ["z"] = 3, ["meta"] = { ["inventory"] = {  }, ["fields"] = {  } }, ["param2"] = 0, ["param1"] = 0 }, { ["y"] = 1, ["x"] = 1, ["name"] = "default:fence_wood", ["z"] = 1, ["meta"] = { ["inventory"] = {  }, ["fields"] = {  } }, ["param2"] = 0, ["param1"] = 60 }, { ["y"] = 1, ["x"] = 1, ["name"] = "default:fence_wood", ["z"] = 3, ["meta"] = { ["inventory"] = {  }, ["fields"] = {  } }, ["param2"] = 0, ["param1"] = 92 }, { ["y"] = 2, ["x"] = 1, ["name"] = "default:fence_wood", ["z"] = 1, ["meta"] = { ["inventory"] = {  }, ["fields"] = {  } }, ["param2"] = 0, ["param1"] = 76 }, { ["y"] = 2, ["x"] = 1, ["name"] = "stairs:slab_woodupside_down", ["z"] = 2, ["meta"] = { ["inventory"] = {  }, ["fields"] = {  } }, ["param2"] = 0, ["param1"] = 92 }, { ["y"] = 2, ["x"] = 1, ["name"] = "default:fence_wood", ["z"] = 3, ["meta"] = { ["inventory"] = {  }, ["fields"] = {  } }, ["param2"] = 0, ["param1"] = 108 }, { ["y"] = 3, ["x"] = 1, ["name"] = "cottages:roof_straw", ["z"] = 0, ["meta"] = { ["inventory"] = {  }, ["fields"] = {  } }, ["param2"] = 0, ["param1"] = 77 }, { ["y"] = 3, ["x"] = 1, ["name"] = "default:fence_wood", ["z"] = 1, ["meta"] = { ["inventory"] = {  }, ["fields"] = {  } }, ["param2"] = 0, ["param1"] = 92 }, { ["y"] = 3, ["x"] = 1, ["name"] = "default:fence_wood", ["z"] = 2, ["meta"] = { ["inventory"] = {  }, ["fields"] = {  } }, ["param2"] = 0, ["param1"] = 108 }, { ["y"] = 3, ["x"] = 1, ["name"] = "default:fence_wood", ["z"] = 3, ["meta"] = { ["inventory"] = {  }, ["fields"] = {  } }, ["param2"] = 0, ["param1"] = 124 }, { ["y"] = 3, ["x"] = 1, ["name"] = "cottages:roof_straw", ["z"] = 4, ["meta"] = { ["inventory"] = {  }, ["fields"] = {  } }, ["param2"] = 2, ["param1"] = 109 }, { ["y"] = 4, ["x"] = 1, ["name"] = "cottages:roof_flat_straw", ["z"] = 1, ["meta"] = { ["inventory"] = {  }, ["fields"] = {  } }, ["param2"] = 0, ["param1"] = 77 }, { ["y"] = 4, ["x"] = 1, ["name"] = "cottages:roof_flat_straw", ["z"] = 2, ["meta"] = { ["inventory"] = {  }, ["fields"] = {  } }, ["param2"] = 0, ["param1"] = 93 }, { ["y"] = 4, ["x"] = 1, ["name"] = "cottages:roof_flat_straw", ["z"] = 3, ["meta"] = { ["inventory"] = {  }, ["fields"] = {  } }, ["param2"] = 2, ["param1"] = 109 }, { ["y"] = 0, ["x"] = 2, ["name"] = "stairs:slab_cobble", ["z"] = 1, ["meta"] = { ["inventory"] = {  }, ["fields"] = {  } }, ["param2"] = 0, ["param1"] = 61 }, { ["y"] = 0, ["x"] = 2, ["name"] = "default:cobble", ["z"] = 2, ["meta"] = { ["inventory"] = {  }, ["fields"] = {  } }, ["param2"] = 0, ["param1"] = 0 }, { ["y"] = 0, ["x"] = 2, ["name"] = "stairs:slab_cobble", ["z"] = 3, ["meta"] = { ["inventory"] = {  }, ["fields"] = {  } }, ["param2"] = 0, ["param1"] = 93 }, { ["y"] = 3, ["x"] = 2, ["name"] = "cottages:roof_flat_straw", ["z"] = 0, ["meta"] = { ["inventory"] = {  }, ["fields"] = {  } }, ["param2"] = 3, ["param1"] = 93 }, { ["y"] = 3, ["x"] = 2, ["name"] = "cottages:roof_straw", ["z"] = 1, ["meta"] = { ["inventory"] = {  }, ["fields"] = {  } }, ["param2"] = 3, ["param1"] = 109 }, { ["y"] = 3, ["x"] = 2, ["name"] = "cottages:roof_straw", ["z"] = 2, ["meta"] = { ["inventory"] = {  }, ["fields"] = {  } }, ["param2"] = 3, ["param1"] = 125 }, { ["y"] = 3, ["x"] = 2, ["name"] = "cottages:roof_straw", ["z"] = 3, ["meta"] = { ["inventory"] = {  }, ["fields"] = {  } }, ["param2"] = 3, ["param1"] = 141 }, { ["y"] = 3, ["x"] = 2, ["name"] = "cottages:roof_flat_straw", ["z"] = 4, ["meta"] = { ["inventory"] = {  }, ["fields"] = {  } }, ["param2"] = 3, ["param1"] = 125 } }
